<?xml version="1.0" ?>
<sdf version="1.5">
	<model name="COL_link_Tail2_collision">
		<pose>0.0 0.0 0.17563073337078094 0.0 0.0 0.0</pose>
		<link name="link_Body">
			<pose>0.0 -0.0943822461822 0.0 0.3490658104419708 -0.0 0.0</pose>
			<inertial>
				<mass>6.980899810791016</mass>
				<pose>6.234424067913524e-06 0.0697533837766855 -0.024842808013829654 -0.3458750247955322 -0.0 0.0</pose>
				<inertia>
					<ixx>5.610949993133545</ixx>
					<ixy>0.0</ixy>
					<ixz>0.0</ixz>
					<iyy>3.1786599159240723</iyy>
					<iyz>0.0</iyz>
					<izz>5.258699893951416</izz>
				</inertia>
			</inertial>
			<collision name="collision_1.001">
				<pose>0.0 0.08081660133061064 -0.028863086158310125 1.3000001907348633 -0.0 0.0</pose>
				<geometry>
					<cylinder>
						<radius>0.057726144790649414</radius>
						<length>0.057726144790649414</length>
					</cylinder>
				</geometry>
			</collision>
			<visual name="VIS_link_Body_visual">
				<pose>-0.00046758178493289115 0.06575123836549324 -0.04567333073696034 -0.3458750247955322 -0.0 0.0</pose>
				<geometry>
					<mesh>
						<uri>model://nrp_mouse_v4_gz/meshes/visual/VIS_link_Body_visual.dae</uri>
						<scale>0.001731784305011086 0.001731784305011086 0.001731784305011086</scale>
					</mesh>
				</geometry>
			</visual>
		</link>
		<link name="link_Body10">
			<pose>0.0 -0.0943822461822 0.0 3.663735981263022e-15 5.164359917954671e-08 -3.141592511700153</pose>
			<inertial>
				<mass>4.14886999130249</mass>
				<pose>1.2642026208813106e-05 0.020593329712063735 -0.002354640360238136 -2.545931547556514e-20 -1.217726413411599e-14 -3.141590118408203</pose>
				<inertia>
					<ixx>1.3100999593734741</ixx>
					<ixy>0.0</ixy>
					<ixz>0.0</ixz>
					<iyy>2.311800003051758</iyy>
					<iyz>0.0</iyz>
					<izz>2.765170097351074</izz>
				</inertia>
			</inertial>
			<collision name="collision_2_1.001">
				<pose>-3.2813514275545352e-15 0.04618091996141516 0.005772622736856192 2.83121238453532e-07 3.410605131648481e-13 6.884538805707052e-08</pose>
				<geometry>
					<box>
						<size>0.057726144790649414 0.057726144790649414 0.057726144790649414</size>
					</box>
				</geometry>
			</collision>
			<collision name="collision_1.003">
				<pose>-1.999573526166045e-15 0.006927138940417521 -0.002886304486935387 0.8000000715255737 3.055333763768431e-13 6.884538805707052e-08</pose>
				<geometry>
					<box>
						<size>0.057726144790649414 0.057726144790649414 0.057726144790649414</size>
					</box>
				</geometry>
			</collision>
			<visual name="VIS_link_Body10_visual">
				<pose>-1.6919468298328072e-15 0.01265940215262873 -0.0026323085910462396 -2.8312129529695085e-07 7.40147130189701e-15 -3.141590118408203</pose>
				<geometry>
					<mesh>
						<uri>model://nrp_mouse_v4_gz/meshes/visual/VIS_link_Body10_visual.dae</uri>
						<scale>0.001731784305011086 0.001731784305011086 0.001731784305011086</scale>
					</mesh>
				</geometry>
			</visual>
		</link>
		<link name="link_LV">
			<pose>0.0609588239452 -0.0995774286252 -0.0169703290362 -1.46607661247253 -5.164359917954668e-08 -9.106158938010539e-09</pose>
			<inertial>
				<mass>0.04395119845867157</mass>
				<pose>0.0002534183881182095 0.01799956952280013 -0.0018197058041309333 1.47353994846344 -4.270086210620902e-15 -1.7080344207208898e-15</pose>
				<inertia>
					<ixx>0.0031014299020171165</ixx>
					<ixy>0.0</ixy>
					<ixz>0.0</ixz>
					<iyy>0.0030027099419385195</iyy>
					<iyz>0.0</iyz>
					<izz>0.0003772609925363213</izz>
				</inertia>
			</inertial>
			<visual name="VIS_link_LV_visual">
				<pose>5.893688620991399e-10 0.017455879987593903 -0.0013898326100618696 1.4735403060913086 -5.510540646014306e-08 -3.455674857377744e-08</pose>
				<geometry>
					<mesh>
						<uri>model://nrp_mouse_v4_gz/meshes/visual/VIS_link_LV_visual.dae</uri>
						<scale>0.001731784305011086 0.001731784305011086 0.001731784305011086</scale>
					</mesh>
				</geometry>
			</visual>
		</link>
		<link name="link_LV4">
			<pose>0.0612185938562 -0.0945799301483 -0.060056530747 -1.2042772173881489 -5.164359917954668e-08 -9.106158938010539e-09</pose>
			<inertial>
				<mass>0.0025772699154913425</mass>
				<pose>-6.03282497642528e-08 0.0036156498139376936 0.00022496867096893913 1.2145800590515137 1.7080362206659027e-15 1.4233635878076645e-15</pose>
				<inertia>
					<ixx>6.647539976256667e-06</ixx>
					<ixy>0.0</ixy>
					<ixz>0.0</ixz>
					<iyy>1.3219600077718496e-05</iyy>
					<iyz>0.0</iyz>
					<izz>9.761370165506378e-06</izz>
				</inertia>
			</inertial>
			<visual name="VIS_link_LV4_visual">
				<pose>-5.286230898978936e-09 0.003934937312649822 0.000494368801727596 1.2145802974700928 3.846883345204333e-08 1.3721150882162192e-09</pose>
				<geometry>
					<mesh>
						<uri>model://nrp_mouse_v4_gz/meshes/visual/VIS_link_LV4_visual.dae</uri>
						<scale>0.001731784305011086 0.001731784305011086 0.001731784305011086</scale>
					</mesh>
				</geometry>
			</visual>
		</link>
		<link name="link_LV3">
			<pose>0.0612185942921 -0.0917270820878 -0.0679938674395 -1.9722220897674518 -5.164359917954668e-08 -9.106158938010539e-09</pose>
			<inertial>
				<mass>0.0032943501137197018</mass>
				<pose>3.6090083133394227e-09 0.004906066036449275 0.0002586003402939019 1.9832099676132202 2.2773774629758796e-15 -2.2773774629758796e-15</pose>
				<inertia>
					<ixx>1.0473199836269487e-05</ixx>
					<ixy>0.0</ixy>
					<ixz>0.0</ixz>
					<iyy>1.8107000869349577e-05</iyy>
					<iyz>0.0</iyz>
					<izz>1.324420009041205e-05</izz>
				</inertia>
			</inertial>
			<collision name="COL_link_LV3_collision">
				<pose>1.047318451051721e-08 0.00460898855545544 0.0006553458940576906 1.9832100868225098 -2.51119445238146e-08 1.8273561863679788e-07</pose>
				<geometry>
					<mesh>
						<uri>model://nrp_mouse_v4_gz/meshes/collisions/COL_link_LV3_collision.dae</uri>
						<scale>0.001731784305011086 0.001731784305011086 0.001731784305011086</scale>
					</mesh>
				</geometry>
			</collision>
			<visual name="VIS_link_LV3_visual">
				<pose>1.047318451051721e-08 0.00460898855545544 0.0006553458940576906 1.9832100868225098 -2.51119445238146e-08 1.8273561863679788e-07</pose>
				<geometry>
					<mesh>
						<uri>model://nrp_mouse_v4_gz/meshes/visual/VIS_link_LV3_visual.dae</uri>
						<scale>0.001731784305011086 0.001731784305011086 0.001731784305011086</scale>
					</mesh>
				</geometry>
			</visual>
		</link>
		<link name="link_LV2">
			<pose>0.0612185947225 -0.0957840943522 -0.0770441636919 -2.775073468685146 -5.164359917954668e-08 -9.106158938010539e-09</pose>
			<inertial>
				<mass>0.0027179899625480175</mass>
				<pose>5.630675178667192e-09 0.003722098764466608 7.897386510580251e-05 2.7928199768066406 -1.821898751655504e-14 -1.0000001111620804e-06</pose>
				<inertia>
					<ixx>7.443929916917114e-06</ixx>
					<ixy>0.0</ixy>
					<ixz>0.0</ixz>
					<iyy>1.0363300134486053e-05</iyy>
					<iyz>0.0</iyz>
					<izz>1.4305999684438575e-05</izz>
				</inertia>
			</inertial>
			<visual name="VIS_link_LV2_visual">
				<pose>5.536075457686509e-09 0.004031714325176239 0.0003951199623962731 2.7928197383880615 -2.2506029040414433e-08 6.067793378861097e-08</pose>
				<geometry>
					<mesh>
						<uri>model://nrp_mouse_v4_gz/meshes/visual/VIS_link_LV2_visual.dae</uri>
						<scale>0.001731784305011086 0.001731784305011086 0.001731784305011086</scale>
					</mesh>
				</geometry>
			</visual>
		</link>
		<link name="link_LV1">
			<pose>0.0620325334532 -0.104219626204 -0.0799650773861 -2.5481806844472845 -5.164359917954668e-08 -9.106158938010539e-09</pose>
			<inertial>
				<mass>0.20825999975204468</mass>
				<pose>-0.0008181599686094554 0.02160375476988463 -0.004462344375919969 2.5595500469207764 -1.9737139914511974e-14 0.0</pose>
				<inertia>
					<ixx>0.027035299688577652</ixx>
					<ixy>0.0</ixy>
					<ixz>0.0</ixz>
					<iyy>0.012903999537229538</iyy>
					<iyz>0.0</iyz>
					<izz>0.01666169986128807</izz>
				</inertia>
			</inertial>
			<collision name="COL_link_LV1_collision">
				<pose>-6.574446811868288e-09 0.019003919942932157 -0.0012703291452940135 2.5595498085021973 -1.1221722928667077e-07 -8.576351717692887e-08</pose>
				<geometry>
					<mesh>
						<uri>model://nrp_mouse_v4_gz/meshes/collisions/COL_link_LV1_collision.dae</uri>
						<scale>0.001731784305011086 0.001731784305011086 0.001731784305011086</scale>
					</mesh>
				</geometry>
			</collision>
			<visual name="VIS_link_LV1_visual">
				<pose>-6.574446811868288e-09 0.019003919942932157 -0.0012703291452940135 2.5595498085021973 -1.1221722928667077e-07 -8.576351717692887e-08</pose>
				<geometry>
					<mesh>
						<uri>model://nrp_mouse_v4_gz/meshes/visual/VIS_link_LV1_visual.dae</uri>
						<scale>0.001731784305011086 0.001731784305011086 0.001731784305011086</scale>
					</mesh>
				</geometry>
			</visual>
		</link>
		<link name="link_Neck">
			<pose>-1.66181160281e-05 -0.138542746124 0.019049628537 4.1342305451410854e-15 -5.164359917954668e-08 -9.106158938010539e-09</pose>
			<inertial>
				<mass>0.38073599338531494</mass>
				<pose>3.0479401327415667e-05 0.020344928469747003 -0.0024124999509353984 -2.1574900150299072 -1.2820406882680453e-21 -9.387621261673206e-15</pose>
				<inertia>
					<ixx>0.025689100846648216</ixx>
					<ixy>0.0</ixy>
					<ixz>0.0</ixz>
					<iyy>0.04173009842634201</iyy>
					<iyz>0.0</iyz>
					<izz>0.0402676984667778</izz>
				</inertia>
			</inertial>
			<visual name="VIS_link_Neck_visual">
				<pose>-1.1464221550018657e-12 -0.006349890515735979 0.011545217947741548 -2.831212668752414e-07 -1.7948606468275174e-13 3.487978338773644e-14</pose>
				<geometry>
					<mesh>
						<uri>model://nrp_mouse_v4_gz/meshes/visual/VIS_link_Neck_visual.dae</uri>
						<scale>0.001731784305011086 0.001731784305011086 0.001731784305011086</scale>
					</mesh>
				</geometry>
			</visual>
		</link>
		<link name="link_Head">
			<pose>0.000796164255663 -0.159008972953 0.0493910692567 -2.967059612274166 -5.164359917954668e-08 -9.106158938010539e-09</pose>
			<inertial>
				<mass>4.173399925231934</mass>
				<pose>-0.00011354731778157046 0.0374448890525656 -0.0015968675868549553 2.9674699306488037 -0.0 5.4847691499497215e-15</pose>
				<inertia>
					<ixx>1.9042099714279175</ixx>
					<ixy>0.0</ixy>
					<ixz>0.0</ixz>
					<iyy>1.5429400205612183</iyy>
					<iyz>0.0</iyz>
					<izz>2.185260057449341</izz>
				</inertia>
			</inertial>
			<collision name="COL_link_Head_collision.001">
				<pose>7.194896224520296e-11 0.032600259692742384 -0.0024992446072786834 2.967470645904541 1.0884812148836964e-11 -1.0459226800624277e-12</pose>
				<geometry>
					<mesh>
						<uri>model://nrp_mouse_v4_gz/meshes/collisions/COL_link_Head_collision.dae</uri>
						<scale>0.001731784305011086 0.001731784305011086 0.001731784305011086</scale>
					</mesh>
				</geometry>
			</collision>
			<visual name="VIS_link_Head_visual">
				<pose>7.194896224520296e-11 0.032600259692742384 -0.0024992446072786834 2.967470645904541 1.0884812148836964e-11 -1.0459226800624277e-12</pose>
				<geometry>
					<mesh>
						<uri>model://nrp_mouse_v4_gz/meshes/visual/VIS_link_Head_visual.dae</uri>
						<scale>0.001731784305011086 0.001731784305011086 0.001731784305011086</scale>
					</mesh>
				</geometry>
			</visual>
		</link>
		<link name="link_RV">
			<pose>-0.060958793192 -0.0995777697843 -0.0169714897028 -1.46607661247253 -5.164359917954668e-08 -9.106158938010539e-09</pose>
			<inertial>
				<mass>0.04395110160112381</mass>
				<pose>-0.0002533622609433017 0.0179918433268611 -0.001835576246691062 1.47353994846344 -5.124097438811157e-15 2.8467208228682246e-15</pose>
				<inertia>
					<ixx>0.0031014299020171165</ixx>
					<ixy>0.0</ixy>
					<ixz>0.0</ixz>
					<iyy>0.0030027099419385195</iyy>
					<iyz>0.0</iyz>
					<izz>0.0003772609925363213</izz>
				</inertia>
			</inertial>
			<visual name="VIS_link_RV_visual">
				<pose>5.884164498472921e-10 0.017454078756877323 -0.0014070726847177362 1.473540186882019 -1.467312813474564e-07 1.7714549827019255e-08</pose>
				<geometry>
					<mesh>
						<uri>model://nrp_mouse_v4_gz/meshes/visual/VIS_link_RV_visual.dae</uri>
						<scale>0.001731784305011086 0.001731784305011086 0.001731784305011086</scale>
					</mesh>
				</geometry>
			</visual>
		</link>
		<link name="link_RV4">
			<pose>-0.0612185585618 -0.0945796943575 -0.0600565340765 -1.2042772173881489 -5.164359917954668e-08 -9.106158938010539e-09</pose>
			<inertial>
				<mass>0.0025772599037736654</mass>
				<pose>-2.316520491060323e-09 0.003615624438433329 0.00022508439294594007 1.2145800590515137 -2.562050413471473e-15 -2.562050413471473e-15</pose>
				<inertia>
					<ixx>6.647539976256667e-06</ixx>
					<ixy>0.0</ixy>
					<ixz>0.0</ixz>
					<iyy>1.3219600077718496e-05</iyy>
					<iyz>0.0</iyz>
					<izz>9.761360161064658e-06</izz>
				</inertia>
			</inertial>
			<visual name="VIS_link_RV4_visual">
				<pose>-9.214776393995762e-09 0.003934918818638167 0.0004944432078675121 1.2145801782608032 -4.251880625361082e-09 -1.3133954723798524e-07</pose>
				<geometry>
					<mesh>
						<uri>model://nrp_mouse_v4_gz/meshes/visual/VIS_link_RV4_visual.dae</uri>
						<scale>0.001731784305011086 0.001731784305011086 0.001731784305011086</scale>
					</mesh>
				</geometry>
			</visual>
		</link>
		<link name="link_RV3">
			<pose>-0.0612185581259 -0.091726846297 -0.067993870769 -1.9722220897674518 -5.164359917954668e-08 -9.106158938010539e-09</pose>
			<inertial>
				<mass>0.0032943501137197018</mass>
				<pose>-3.732220188261596e-09 0.004906100013819525 0.00025872619634415006 1.9832099676132202 2.2773829686900367e-15 -2.2773829686900367e-15</pose>
				<inertia>
					<ixx>1.0473199836269487e-05</ixx>
					<ixy>0.0</ixy>
					<ixz>0.0</ixz>
					<iyy>1.810690082493238e-05</iyy>
					<iyz>0.0</iyz>
					<izz>1.324420009041205e-05</izz>
				</inertia>
			</inertial>
			<collision name="COL_link_RV3_collision">
				<pose>-3.751875483312648e-09 0.004609063821781945 0.0006554236334206376 1.9832102060317993 1.1462435622888734e-07 -1.3443727198136912e-07</pose>
				<geometry>
					<mesh>
						<uri>model://nrp_mouse_v4_gz/meshes/collisions/COL_link_RV3_collision.dae</uri>
						<scale>0.001731784305011086 0.001731784305011086 0.001731784305011086</scale>
					</mesh>
				</geometry>
			</collision>
			<visual name="VIS_link_RV3_visual">
				<pose>-3.751875483312648e-09 0.004609063821781945 0.0006554236334206376 1.9832102060317993 1.1462435622888734e-07 -1.3443727198136912e-07</pose>
				<geometry>
					<mesh>
						<uri>model://nrp_mouse_v4_gz/meshes/visual/VIS_link_RV3_visual.dae</uri>
						<scale>0.001731784305011086 0.001731784305011086 0.001731784305011086</scale>
					</mesh>
				</geometry>
			</visual>
		</link>
		<link name="link_RV2">
			<pose>-0.0612185576955 -0.0957838585614 -0.0770441670214 -2.775073468685146 -5.164359917954668e-08 -9.106158938010539e-09</pose>
			<inertial>
				<mass>0.0027179899625480175</mass>
				<pose>-4.15131480275779e-09 0.00372213188165027 7.892198510217607e-05 2.7928199768066406 -3.4160618534199647e-14 0.0</pose>
				<inertia>
					<ixx>7.443949925800553e-06</ixx>
					<ixy>0.0</ixy>
					<ixz>0.0</ixz>
					<iyy>1.0363300134486053e-05</iyy>
					<iyz>0.0</iyz>
					<izz>1.4305999684438575e-05</izz>
				</inertia>
			</inertial>
			<visual name="VIS_link_RV2_visual">
				<pose>2.6200409862509044e-09 0.004031730238628128 0.0003950852861244192 2.7928199768066406 1.6318162820994075e-08 -4.087031513222428e-08</pose>
				<geometry>
					<mesh>
						<uri>model://nrp_mouse_v4_gz/meshes/visual/VIS_link_RV2_visual.dae</uri>
						<scale>0.001731784305011086 0.001731784305011086 0.001731784305011086</scale>
					</mesh>
				</geometry>
			</visual>
		</link>
		<link name="link_RV1">
			<pose>-0.0620324962782 -0.104219390398 -0.0799650807997 -2.5481806844472845 -5.164359917954668e-08 -9.106158938010539e-09</pose>
			<inertial>
				<mass>0.20825999975204468</mass>
				<pose>0.0008180387898237829 0.021605578365452516 -0.004461589132095156 2.5595500469207764 1.0000001111620804e-06 -1.3158092711652684e-14</pose>
				<inertia>
					<ixx>0.027035299688577652</ixx>
					<ixy>0.0</ixy>
					<ixz>0.0</ixz>
					<iyy>0.012903999537229538</iyy>
					<iyz>0.0</iyz>
					<izz>0.01666169986128807</izz>
				</inertia>
			</inertial>
			<collision name="COL_link_RV1_collision">
				<pose>3.315132940501209e-10 0.019004133269206136 -0.0012701734515214724 2.5595500469207764 8.795061603450449e-07 8.644993698680992e-08</pose>
				<geometry>
					<mesh>
						<uri>model://nrp_mouse_v4_gz/meshes/collisions/COL_link_RV1_collision.dae</uri>
						<scale>0.001731784305011086 0.001731784305011086 0.001731784305011086</scale>
					</mesh>
				</geometry>
			</collision>
			<visual name="VIS_link_RV1_visual">
				<pose>3.315132940501209e-10 0.019004133269206136 -0.0012701734515214724 2.5595500469207764 8.795061603450449e-07 8.644993698680992e-08</pose>
				<geometry>
					<mesh>
						<uri>model://nrp_mouse_v4_gz/meshes/visual/VIS_link_RV1_visual.dae</uri>
						<scale>0.001731784305011086 0.001731784305011086 0.001731784305011086</scale>
					</mesh>
				</geometry>
			</visual>
		</link>
		<link name="link_Body8">
			<pose>0.0 0.00161959342785 0.0349433478837 -0.13962638378143313 -0.0 0.0</pose>
			<inertial>
				<mass>0.044343799352645874</mass>
				<pose>-5.772614464490491e-08 0.006819102515539299 0.0028441325491481706 0.14189699292182922 -0.0 0.0</pose>
				<inertia>
					<ixx>0.0008347990224137902</ixx>
					<ixy>0.0</ixy>
					<ixz>0.0</ixz>
					<iyy>0.0013697199756279588</iyy>
					<iyz>0.0</iyz>
					<izz>0.0009616889874450862</izz>
				</inertia>
			</inertial>
			<visual name="VIS_link_Body8_visual">
				<pose>0.0 0.006299139507007112 0.0007249609559600856 0.14189700782299042 -0.0 0.0</pose>
				<geometry>
					<mesh>
						<uri>model://nrp_mouse_v4_gz/meshes/visual/VIS_link_Body8_visual.dae</uri>
						<scale>0.001731784305011086 0.001731784305011086 0.001731784305011086</scale>
					</mesh>
				</geometry>
			</visual>
		</link>
		<link name="link_Body7">
			<pose>0.0 0.0137461139873 0.0332380401241 -0.20943954586982733 -0.0 0.0</pose>
			<inertial>
				<mass>0.047821901738643646</mass>
				<pose>0.0 0.005553918576325145 0.002313136787430281 0.21109294891357422 -0.0 0.0</pose>
				<inertia>
					<ixx>0.0009753779741004109</ixx>
					<ixy>0.0</ixy>
					<ixz>0.0</ixz>
					<iyy>0.0015365199651569128</iyy>
					<iyz>0.0</iyz>
					<izz>0.0010528500424697995</izz>
				</inertia>
			</inertial>
			<visual name="VIS_link_Body7_visual">
				<pose>0.0 0.006773427467869908 0.00021171944543141308 0.21109288930892944 -0.0 0.0</pose>
				<geometry>
					<mesh>
						<uri>model://nrp_mouse_v4_gz/meshes/visual/VIS_link_Body7_visual.dae</uri>
						<scale>0.001731784305011086 0.001731784305011086 0.001731784305011086</scale>
					</mesh>
				</geometry>
			</visual>
		</link>
		<link name="link_Body6">
			<pose>0.0 0.0258726460555 0.0306605733382 -0.26179942488670355 -0.0 0.0</pose>
			<inertial>
				<mass>0.0492452010512352</mass>
				<pose>0.0 0.00667032722373051 0.0029715713427194146 0.2558090090751648 -0.0 0.0</pose>
				<inertia>
					<ixx>0.0010030199773609638</ixx>
					<ixy>0.0</ixy>
					<ixz>0.0</ixz>
					<iyy>0.001555750030092895</iyy>
					<iyz>0.0</iyz>
					<izz>0.001109299948439002</izz>
				</inertia>
			</inertial>
			<visual name="VIS_link_Body6_visual">
				<pose>0.0 0.00596351534460382 0.0008794048773879126 0.2558090090751648 -0.0 0.0</pose>
				<geometry>
					<mesh>
						<uri>model://nrp_mouse_v4_gz/meshes/visual/VIS_link_Body6_visual.dae</uri>
						<scale>0.001731784305011086 0.001731784305011086 0.001731784305011086</scale>
					</mesh>
				</geometry>
			</visual>
		</link>
		<link name="link_Body5">
			<pose>0.0 0.0371113211115 0.0276488943578 -0.3316125869750977 -0.0 0.0</pose>
			<inertial>
				<mass>0.05512990057468414</mass>
				<pose>-1.1545229716505324e-06 0.005752453081726117 0.0020064566134543327 0.31745895743370056 -0.0 0.0</pose>
				<inertia>
					<ixx>0.0012408599723130465</ixx>
					<ixy>0.0</ixy>
					<ixz>0.0</ixz>
					<iyy>0.0018117999425157905</iyy>
					<iyz>0.0</iyz>
					<izz>0.0012896900298073888</izz>
				</inertia>
			</inertial>
			<visual name="VIS_link_Body5_visual">
				<pose>0.0 0.0070051840996967485 0.00020529213124120815 0.3174589276313782 -0.0 0.0</pose>
				<geometry>
					<mesh>
						<uri>model://nrp_mouse_v4_gz/meshes/visual/VIS_link_Body5_visual.dae</uri>
						<scale>0.001731784305011086 0.001731784305011086 0.001731784305011086</scale>
					</mesh>
				</geometry>
			</visual>
		</link>
		<link name="link_Body4">
			<pose>0.0 0.0491766520237 0.0234948897192 -0.38397246599197393 -0.0 0.0</pose>
			<inertial>
				<mass>0.05352329835295677</mass>
				<pose>-5.772614464490491e-08 0.006672969716930766 0.0028329763591870005 0.367173969745636 -0.0 0.0</pose>
				<inertia>
					<ixx>0.001153470017015934</ixx>
					<ixy>0.0</ixy>
					<ixz>0.0</ixz>
					<iyy>0.001706180046312511</iyy>
					<iyz>0.0</iyz>
					<izz>0.0012537100119516253</izz>
				</inertia>
			</inertial>
			<visual name="VIS_link_Body4_visual">
				<pose>0.0 0.00583126681772228 0.0007584712448931441 0.3671739995479584 -0.0 0.0</pose>
				<geometry>
					<mesh>
						<uri>model://nrp_mouse_v4_gz/meshes/visual/VIS_link_Body4_visual.dae</uri>
						<scale>0.001731784305011086 0.001731784305011086 0.001731784305011086</scale>
					</mesh>
				</geometry>
			</visual>
		</link>
		<link name="link_Body3">
			<pose>0.0 0.0603587726392 0.0189766366904 -0.45378562808036804 -0.0 0.0</pose>
			<inertial>
				<mass>0.06284330040216446</mass>
				<pose>0.0 0.005440893499326194 0.0015790445207386483 0.4444189965724945 -0.0 0.0</pose>
				<inertia>
					<ixx>0.0015455300454050303</ixx>
					<ixy>0.0</ixy>
					<ixz>0.0</ixz>
					<iyy>0.002082840073853731</iyy>
					<iyz>0.0</iyz>
					<izz>0.0015836600214242935</izz>
				</inertia>
			</inertial>
			<visual name="VIS_link_Body3_visual">
				<pose>0.0 0.006444786300193073 -7.225567344448791e-08 0.44441893696784973 -0.0 0.0</pose>
				<geometry>
					<mesh>
						<uri>model://nrp_mouse_v4_gz/meshes/visual/VIS_link_Body3_visual.dae</uri>
						<scale>0.001731784305011086 0.001731784305011086 0.001731784305011086</scale>
					</mesh>
				</geometry>
			</visual>
		</link>
		<link name="link_Body2">
			<pose>0.0 0.0712204938956 0.0136796246773 -0.4886922091245651 -0.0 0.0</pose>
			<inertial>
				<mass>0.06944669783115387</mass>
				<pose>0.0 0.007770540278045246 0.0013863489619012626 0.4829689562320709 -0.0 0.0</pose>
				<inertia>
					<ixx>0.0019178499933332205</ixx>
					<ixy>0.0</ixy>
					<ixz>0.0</ixz>
					<iyy>0.0024799599777907133</iyy>
					<iyz>0.0</iyz>
					<izz>0.001781729981303215</izz>
				</inertia>
			</inertial>
			<visual name="VIS_BezierCurve_2">
				<pose>-1.674058177639215e-05 0.016034875828410122 -1.8580030314296891e-07 0.36651888489723206 -0.0 0.0</pose>
				<geometry>
					<mesh>
						<uri>model://nrp_mouse_v4_gz/meshes/visual/VIS_BezierCurve_2.dae</uri>
						<scale>0.057726144790649414 0.057726144790649414 0.057726144790649414</scale>
					</mesh>
				</geometry>
			</visual>
			<visual name="VIS_link_Body2_visual_1">
				<pose>0.0 0.008012383457810301 -0.0005501374938745585 0.48296889662742615 -0.0 0.0</pose>
				<geometry>
					<mesh>
						<uri>model://nrp_mouse_v4_gz/meshes/visual/VIS_link_Body2_visual_1.dae</uri>
						<scale>0.001731784305011086 0.001731784305011086 0.001731784305011086</scale>
					</mesh>
				</geometry>
			</visual>
			<visual name="VIS_BezierCurve.001">
				<pose>-1.674058177639215e-05 0.016034875828410122 -1.8580030314296891e-07 0.36651888489723206 -0.0 0.0</pose>
				<geometry>
					<mesh>
						<uri>model://nrp_mouse_v4_gz/meshes/visual/VIS_BezierCurve.dae</uri>
						<scale>0.057726144790649414 0.057726144790649414 0.057726144790649414</scale>
					</mesh>
				</geometry>
			</visual>
		</link>
		<link name="link_Body1">
			<pose>-1.67405817764e-05 0.0853783921953 0.00615152650828 -0.122173085808754 -0.0 0.0</pose>
			<inertial>
				<mass>3.9979500770568848</mass>
				<pose>2.6727206945964532e-05 0.018846639986321634 -0.007629770742816788 0.10866101086139679 -0.0 0.0</pose>
				<inertia>
					<ixx>1.0189900398254395</ixx>
					<ixy>0.0</ixy>
					<ixz>0.0</ixz>
					<iyy>2.804460048675537</iyy>
					<iyz>0.0</iyz>
					<izz>3.050489902496338</izz>
				</inertia>
			</inertial>
			<collision name="collision_1.002">
				<pose>0.0 0.02886308271756377 -0.005772602952564654 -0.4000001847743988 -0.0 0.0</pose>
				<geometry>
					<box>
						<size>0.057726144790649414 0.057726144790649414 0.057726144790649414</size>
					</box>
				</geometry>
			</collision>
			<visual name="VIS_link_Body1_visual_1">
				<pose>0.0 0.02204372472660765 -0.0070894660418368005 0.10866091400384903 -0.0 0.0</pose>
				<geometry>
					<mesh>
						<uri>model://nrp_mouse_v4_gz/meshes/visual/VIS_link_Body1_visual_1.dae</uri>
						<scale>0.001731784305011086 0.001731784305011086 0.001731784305011086</scale>
					</mesh>
				</geometry>
			</visual>
			<visual name="VIS_link_Body1_axis">
				<pose>0.0 1.0322239063498273e-08 3.4407463544994243e-09 -1.5646223516796454e-07 -0.0 0.0</pose>
				<geometry>
					<mesh>
						<uri>model://nrp_mouse_v4_gz/meshes/visual/VIS_link_Body1_axis.dae</uri>
						<scale>0.057726144790649414 0.057726144790649414 0.057726144790649414</scale>
					</mesh>
				</geometry>
			</visual>
		</link>
		<link name="link_LH">
			<pose>0.0715226933386 0.0979926630833 -0.00873954862361 -3.001966252923012 -0.0 0.0</pose>
			<inertial>
				<mass>0.07556319981813431</mass>
				<pose>0.00025671408550920205 0.019920058228400706 0.0015226954176910112 2.9820399284362793 9.999999974752427e-07 -9.999999974752427e-07</pose>
				<inertia>
					<ixx>0.006539409980177879</ixx>
					<ixy>0.0</ixy>
					<ixz>0.0</ixz>
					<iyy>0.0013326900079846382</iyy>
					<iyz>0.0</iyz>
					<izz>0.005685599986463785</izz>
				</inertia>
			</inertial>
			<visual name="VIS_link_LH_visual">
				<pose>0.0 0.018809725939057387 0.002217721020180363 2.9820399284362793 1.9701860765053425e-06 5.960629323453759e-08</pose>
				<geometry>
					<mesh>
						<uri>model://nrp_mouse_v4_gz/meshes/visual/VIS_link_LH_visual.dae</uri>
						<scale>0.001731784305011086 0.001731784305011086 0.001731784305011086</scale>
					</mesh>
				</geometry>
			</visual>
		</link>
		<link name="link_LH10">
			<pose>0.071782460979 0.0512806895547 -0.014650303544 -3.089232712984085 -0.0 0.0</pose>
			<inertial>
				<mass>0.0028363000601530075</mass>
				<pose>7.296757576210158e-09 0.005392754017080392 -0.000424652829186023 3.0679500102996826 -9.339802440152438e-16 9.999999974752427e-07</pose>
				<inertia>
					<ixx>1.2842900105169974e-05</ixx>
					<ixy>0.0</ixy>
					<ixz>0.0</ixz>
					<iyy>9.985319593397435e-06</iyy>
					<iyz>0.0</iyz>
					<izz>2.0832700101891533e-05</izz>
				</inertia>
			</inertial>
			<visual name="VIS_link_LH10_visual">
				<pose>7.2907116862048886e-09 0.005342039136188248 -0.0007935810507877505 3.0679500102996826 -6.850166143891156e-16 7.91623477880421e-09</pose>
				<geometry>
					<mesh>
						<uri>model://nrp_mouse_v4_gz/meshes/visual/VIS_link_LH10_visual.dae</uri>
						<scale>0.001731784305011086 0.001731784305011086 0.001731784305011086</scale>
					</mesh>
				</geometry>
			</visual>
		</link>
		<link name="link_LH9">
			<pose>0.071782460979 0.0394797306065 -0.0156985783325 -2.23402139544487 -0.0 0.0</pose>
			<inertial>
				<mass>0.0050949398428201675</mass>
				<pose>-6.8814869666338505e-09 0.005097476046429961 -0.00022906252743126743 2.204430103302002 -2.1718519594471217e-21 7.449833762000135e-22</pose>
				<inertia>
					<ixx>2.2689999241265468e-05</ixx>
					<ixy>0.0</ixy>
					<ixz>0.0</ixz>
					<iyy>2.986999970744364e-05</iyy>
					<iyz>0.0</iyz>
					<izz>2.5109999114647508e-05</izz>
				</inertia>
			</inertial>
			<collision name="COL_link_LH9_collision">
				<pose>-6.8814869666338505e-09 0.005260913218641861 -0.0006685989501136191 2.204430103302002 -5.960464477539063e-08 5.960464477539063e-08</pose>
				<geometry>
					<mesh>
						<uri>model://nrp_mouse_v4_gz/meshes/collisions/COL_link_LH9_collision.dae</uri>
						<scale>0.001731784305011086 0.001731784305011086 0.001731784305011086</scale>
					</mesh>
				</geometry>
			</collision>
			<visual name="VIS_link_LH9_visual">
				<pose>-6.8814869666338505e-09 0.005260913218641861 -0.0006685989501136191 2.204430103302002 -5.960464477539063e-08 5.960464477539063e-08</pose>
				<geometry>
					<mesh>
						<uri>model://nrp_mouse_v4_gz/meshes/visual/VIS_link_LH9_visual.dae</uri>
						<scale>0.001731784305011086 0.001731784305011086 0.001731784305011086</scale>
					</mesh>
				</geometry>
			</visual>
		</link>
		<link name="link_LH8">
			<pose>0.071782460979 0.0327875255787 -0.0252026012013 -1.378810077905655 -0.0 0.0</pose>
			<inertial>
				<mass>0.0032894399482756853</mass>
				<pose>0.0 0.005476385658159444 -0.00019990392245006205 1.3539199829101562 4.257851618599189e-22 -1.9512942758475066e-22</pose>
				<inertia>
					<ixx>1.4321900380309671e-05</ixx>
					<ixy>0.0</ixy>
					<ixz>0.0</ixz>
					<iyy>2.3052200049278326e-05</iyy>
					<iyz>0.0</iyz>
					<izz>1.2116600373701658e-05</izz>
				</inertia>
			</inertial>
			<visual name="VIS_link_LH8_visual">
				<pose>1.3762985417997697e-08 0.0051948409964897024 -0.000648205646470501 1.3539199829101562 -1.4789532748750006e-17 -6.015980163545835e-19</pose>
				<geometry>
					<mesh>
						<uri>model://nrp_mouse_v4_gz/meshes/visual/VIS_link_LH8_visual.dae</uri>
						<scale>0.001731784305011086 0.001731784305011086 0.001731784305011086</scale>
					</mesh>
				</geometry>
			</visual>
		</link>
		<link name="link_LH7">
			<pose>0.0732025240941 0.0356282283386 -0.0363604881679 -1.2042771577835083 -0.0 0.0</pose>
			<inertial>
				<mass>0.04902980104088783</mass>
				<pose>-0.0005636905937649317 0.01005703149561299 0.0034260509268193573 1.1872700452804565 -2.885909413320477e-22 1.8381588740465852e-23</pose>
				<inertia>
					<ixx>0.0028128100093454123</ixx>
					<ixy>0.0</ixy>
					<ixz>0.0</ixz>
					<iyy>0.002701960038393736</iyy>
					<iyz>0.0</iyz>
					<izz>0.0005245479987934232</izz>
				</inertia>
			</inertial>
			<collision name="COL_link_LH7_collision">
				<pose>6.881492708998849e-09 0.008006100654966986 0.0038282776164066945 1.1872700452804565 -4.17797600960057e-08 2.156751293114212e-07</pose>
				<geometry>
					<mesh>
						<uri>model://nrp_mouse_v4_gz/meshes/collisions/COL_link_LH7_collision.dae</uri>
						<scale>0.001731784305011086 0.001731784305011086 0.001731784305011086</scale>
					</mesh>
				</geometry>
			</collision>
			<visual name="VIS_link_LH7_visual">
				<pose>6.881492708998849e-09 0.008006100654966986 0.0038282776164066945 1.1872700452804565 -4.17797600960057e-08 2.156751293114212e-07</pose>
				<geometry>
					<mesh>
						<uri>model://nrp_mouse_v4_gz/meshes/visual/VIS_link_LH7_visual.dae</uri>
						<scale>0.001731784305011086 0.001731784305011086 0.001731784305011086</scale>
					</mesh>
				</geometry>
			</visual>
		</link>
		<link name="link_LH6">
			<pose>0.071782460979 0.0475799359081 -0.0668744938675 -0.45378559827804554 -0.0 0.0</pose>
			<inertial>
				<mass>0.003684809897094965</mass>
				<pose>-6.881492708998849e-09 0.0048769448495846746 -7.146774252930754e-05 0.4407519996166229 1.0180701841403668e-22 -9.50198889018107e-22</pose>
				<inertia>
					<ixx>1.3643199963553343e-05</ixx>
					<ixy>0.0</ixy>
					<ixz>0.0</ixz>
					<iyy>1.4911000107531436e-05</iyy>
					<iyz>0.0</iyz>
					<izz>2.208459954999853e-05</izz>
				</inertia>
			</inertial>
			<visual name="VIS_link_LH6_visual">
				<pose>-1.3762985417997697e-08 0.005120721728800959 -0.0006672381349304146 0.44075194001197815 4.0525502953414616e-08 1.3403020204805216e-07</pose>
				<geometry>
					<mesh>
						<uri>model://nrp_mouse_v4_gz/meshes/visual/VIS_link_LH6_visual.dae</uri>
						<scale>0.001731784305011086 0.001731784305011086 0.001731784305011086</scale>
					</mesh>
				</geometry>
			</visual>
		</link>
		<link name="link_LH5">
			<pose>0.0717651431347 0.0575671112337 -0.0713344717206 0.4363323450088501 -0.0 0.0</pose>
			<inertial>
				<mass>0.0042989300563931465</mass>
				<pose>-0.001111966643861706 0.005168303810137331 5.58725596775389e-05 -0.455452024936676 -2.0870453731680282e-22 -8.312807959940044e-23</pose>
				<inertia>
					<ixx>1.4717699741595425e-05</ixx>
					<ixy>0.0</ixy>
					<ixz>0.0</ixz>
					<iyy>2.366519947827328e-05</iyy>
					<iyz>0.0</iyz>
					<izz>3.0231200071284547e-05</izz>
				</inertia>
			</inertial>
			<visual name="VIS_link_LH5_visual">
				<pose>6.881492708998849e-09 0.0049133617090006965 -0.0004009673764215904 -0.45545193552970886 2.9524929835130866e-18 1.4504797329574552e-17</pose>
				<geometry>
					<mesh>
						<uri>model://nrp_mouse_v4_gz/meshes/visual/VIS_link_LH5_visual.dae</uri>
						<scale>0.001731784305011086 0.001731784305011086 0.001731784305011086</scale>
					</mesh>
				</geometry>
			</visual>
		</link>
		<link name="link_LH4">
			<pose>0.0711243829408 0.0671894702709 -0.0663226653999 -0.1745328903198242 -0.0 0.0</pose>
			<inertial>
				<mass>0.01053799968212843</mass>
				<pose>-0.0015169233506346913 0.004091784165312973 0.0034807768577742593 0.1470780074596405 -6.560417083761346e-17 1.5419740349281578e-15</pose>
				<inertia>
					<ixx>6.891380326123908e-05</ixx>
					<ixy>0.0</ixy>
					<ixz>0.0</ixz>
					<iyy>9.493489778833464e-05</iyy>
					<iyz>0.0</iyz>
					<izz>0.00010201599798165262</izz>
				</inertia>
			</inertial>
			<visual name="VIS_link_LH4_visual">
				<pose>-1.5383376432503216e-09 0.004430885201907486 0.0022319347433708003 0.14707908034324646 1.156854560063758e-13 -4.097817196679898e-08</pose>
				<geometry>
					<mesh>
						<uri>model://nrp_mouse_v4_gz/meshes/visual/VIS_link_LH4_visual.dae</uri>
						<scale>0.001731784305011086 0.001731784305011086 0.001731784305011086</scale>
					</mesh>
				</geometry>
			</visual>
		</link>
		<link name="link_LH3">
			<pose>0.0717824610025 0.077505123654 -0.0692038070209 -1.239183783531189 -0.0 0.0</pose>
			<inertial>
				<mass>0.0017467200523242354</mass>
				<pose>-3.2936231691824286e-11 0.002660130466068722 -3.0877257785277834e-05 1.212030053138733 -8.14670415686837e-18 -3.5584003006663417e-17</pose>
				<inertia>
					<ixx>3.0667399641970405e-06</ixx>
					<ixy>0.0</ixy>
					<ixz>0.0</ixz>
					<iyy>7.87526005296968e-06</iyy>
					<iyz>0.0</iyz>
					<izz>6.2613598856842145e-06</izz>
				</inertia>
			</inertial>
			<visual name="VIS_link_LH3_visual">
				<pose>6.8486525337429545e-09 0.0028719634561298335 0.0003097531905638107 1.2120299339294434 9.121379207499558e-08 -4.081561044699811e-08</pose>
				<geometry>
					<mesh>
						<uri>model://nrp_mouse_v4_gz/meshes/visual/VIS_link_LH3_visual.dae</uri>
						<scale>0.001731784305011086 0.001731784305011086 0.001731784305011086</scale>
					</mesh>
				</geometry>
			</visual>
		</link>
		<link name="link_LH2">
			<pose>0.0717824610025 0.0794031341573 -0.0758388571812 -2.042035162448883 -0.0 0.0</pose>
			<inertial>
				<mass>0.0018450700445100665</mass>
				<pose>-3.3309547967470203e-09 0.0032836433812795107 -2.342804192778658e-05 2.0214600563049316 9.563859595360146e-16 0.0</pose>
				<inertia>
					<ixx>3.1458700959774433e-06</ixx>
					<ixy>0.0</ixy>
					<ixz>0.0</ixz>
					<iyy>8.017519576242194e-06</iyy>
					<iyz>0.0</iyz>
					<izz>6.821509941801196e-06</izz>
				</inertia>
			</inertial>
			<visual name="VIS_link_LH2_visual">
				<pose>-1.0218086508174121e-08 0.0030776562192746937 0.00019980070005942707 2.0214600563049316 -9.799351374795151e-08 7.787755151866804e-08</pose>
				<geometry>
					<mesh>
						<uri>model://nrp_mouse_v4_gz/meshes/visual/VIS_link_LH2_visual.dae</uri>
						<scale>0.001731784305011086 0.001731784305011086 0.001731784305011086</scale>
					</mesh>
				</geometry>
			</visual>
		</link>
		<link name="link_LH1">
			<pose>0.0717824610025 0.0758160005565 -0.0818279262327 -2.583087205886841 -0.0 0.0</pose>
			<inertial>
				<mass>0.05634620040655136</mass>
				<pose>-1.3951182407097946e-08 0.018482751812989306 -0.0008586795417215853 2.5660500526428223 1.5779833113400694e-15 -4.934339612253091e-15</pose>
				<inertia>
					<ixx>0.002188999904319644</ixx>
					<ixy>0.0</ixy>
					<ixz>0.0</ixz>
					<iyy>0.0009492419776506722</iyy>
					<iyz>0.0</iyz>
					<izz>0.0019243600545451045</izz>
				</inertia>
			</inertial>
			<collision name="COL_link_LH1_collision">
				<pose>-1.3485780130749318e-10 0.019203412696192856 -0.0002797430008598667 2.5660500526428223 -1.1313520076328132e-07 2.394065745647822e-08</pose>
				<geometry>
					<mesh>
						<uri>model://nrp_mouse_v4_gz/meshes/collisions/COL_link_LH1_collision.dae</uri>
						<scale>0.001731784305011086 0.001731784305011086 0.001731784305011086</scale>
					</mesh>
				</geometry>
			</collision>
			<visual name="VIS_link_LH1_visual">
				<pose>-1.3485780130749318e-10 0.019203412696192856 -0.0002797430008598667 2.5660500526428223 -1.1313520076328132e-07 2.394065745647822e-08</pose>
				<geometry>
					<mesh>
						<uri>model://nrp_mouse_v4_gz/meshes/visual/VIS_link_LH1_visual.dae</uri>
						<scale>0.001731784305011086 0.001731784305011086 0.001731784305011086</scale>
					</mesh>
				</geometry>
			</visual>
		</link>
		<link name="link_RH">
			<pose>-0.0715226960401 0.0979926630833 -0.00873954862361 -3.001966252923012 -0.0 0.0</pose>
			<inertial>
				<mass>0.07556319981813431</mass>
				<pose>-0.00025676913745087404 0.019919989413473616 0.00152235220324215 2.9820399284362793 -0.0 0.0</pose>
				<inertia>
					<ixx>0.006539409980177879</ixx>
					<ixy>0.0</ixy>
					<ixz>0.0</ixz>
					<iyy>0.0013326900079846382</iyy>
					<iyz>0.0</iyz>
					<izz>0.005685599986463785</izz>
				</inertia>
			</inertial>
			<visual name="VIS_link_RH_visual">
				<pose>0.0 0.018810001198765747 0.0022177932758538077 2.9820399284362793 9.251857126821392e-16 -5.960465188081798e-08</pose>
				<geometry>
					<mesh>
						<uri>model://nrp_mouse_v4_gz/meshes/visual/VIS_link_RH_visual.dae</uri>
						<scale>0.001731784305011086 0.001731784305011086 0.001731784305011086</scale>
					</mesh>
				</geometry>
			</visual>
		</link>
		<link name="link_RH10">
			<pose>-0.0717824636805 0.0512806895547 -0.014650303544 -3.089232712984085 -0.0 0.0</pose>
			<inertial>
				<mass>0.0028363000601530075</mass>
				<pose>-7.296771521953725e-09 0.005392864120963736 -0.00042468637646297935 3.0679500102996826 -3.62077235259591e-15 -9.999999974752427e-07</pose>
				<inertia>
					<ixx>1.2842900105169974e-05</ixx>
					<ixy>0.0</ixy>
					<ixz>0.0</ixz>
					<iyy>9.985319593397435e-06</iyy>
					<iyz>0.0</iyz>
					<izz>2.0832700101891533e-05</izz>
				</inertia>
			</inertial>
			<visual name="VIS_link_RH10_visual">
				<pose>-4.092256424511271e-10 0.005342087306637211 -0.0007935561053766804 3.0679500102996826 -1.4580542245031143e-14 7.450594807778543e-09</pose>
				<geometry>
					<mesh>
						<uri>model://nrp_mouse_v4_gz/meshes/visual/VIS_link_RH10_visual.dae</uri>
						<scale>0.001731784305011086 0.001731784305011086 0.001731784305011086</scale>
					</mesh>
				</geometry>
			</visual>
		</link>
		<link name="link_RH9">
			<pose>-0.0717824636805 0.0394797306065 -0.0156985783325 -2.23402139544487 -0.0 0.0</pose>
			<inertial>
				<mass>0.0050949398428201675</mass>
				<pose>-7.408676270025474e-15 0.005097118208809093 -0.00022900403474324094 2.204430103302002 -8.687500734048686e-21 0.0</pose>
				<inertia>
					<ixx>2.2689799152431078e-05</ixx>
					<ixy>0.0</ixy>
					<ixz>0.0</ixz>
					<iyy>2.9865499527659267e-05</iyy>
					<iyz>0.0</iyz>
					<izz>2.511360071366653e-05</izz>
				</inertia>
			</inertial>
			<collision name="COL_link_RH9_collision">
				<pose>-6.881500092039561e-09 0.005260574305125942 -0.0006685094907084022 2.204430103302002 5.960470872423684e-08 2.870720442637491e-15</pose>
				<geometry>
					<mesh>
						<uri>model://nrp_mouse_v4_gz/meshes/collisions/COL_link_RH9_collision.dae</uri>
						<scale>0.001731784305011086 0.001731784305011086 0.001731784305011086</scale>
					</mesh>
				</geometry>
			</collision>
			<visual name="VIS_link_RH9_visual">
				<pose>-6.881500092039561e-09 0.005260574305125942 -0.0006685094907084022 2.204430103302002 5.960470872423684e-08 2.870720442637491e-15</pose>
				<geometry>
					<mesh>
						<uri>model://nrp_mouse_v4_gz/meshes/visual/VIS_link_RH9_visual.dae</uri>
						<scale>0.001731784305011086 0.001731784305011086 0.001731784305011086</scale>
					</mesh>
				</geometry>
			</visual>
		</link>
		<link name="link_RH8">
			<pose>-0.0717824636805 0.0327881027451 -0.0252026013054 -1.378810077905655 -0.0 0.0</pose>
			<inertial>
				<mass>0.0032894399482756853</mass>
				<pose>-6.88149229882992e-09 0.0054762914677279895 -0.00019996241513808855 1.3539199829101562 4.072266347738556e-22 -5.429688463651408e-22</pose>
				<inertia>
					<ixx>1.4321900380309671e-05</ixx>
					<ixy>0.0</ixy>
					<ixz>0.0</ixz>
					<iyy>2.3052200049278326e-05</iyy>
					<iyz>0.0</iyz>
					<izz>1.2116600373701658e-05</izz>
				</inertia>
			</inertial>
			<visual name="VIS_link_RH8_visual">
				<pose>-6.88149229882992e-09 0.005194706807381877 -0.0006483243522197313 1.3539198637008667 -1.2889895399014134e-15 -1.347471447436929e-15</pose>
				<geometry>
					<mesh>
						<uri>model://nrp_mouse_v4_gz/meshes/visual/VIS_link_RH8_visual.dae</uri>
						<scale>0.001731784305011086 0.001731784305011086 0.001731784305011086</scale>
					</mesh>
				</geometry>
			</visual>
		</link>
		<link name="link_RH7">
			<pose>-0.0732025267956 0.0356282282303 -0.0363599108454 -1.2042771577835083 -0.0 0.0</pose>
			<inertial>
				<mass>0.04902980104088783</mass>
				<pose>0.0005636355418232597 0.01005714331986951 0.0034261059787610293 1.1872700452804565 -4.705749422534892e-22 -2.352874711267446e-22</pose>
				<inertia>
					<ixx>0.0028128100093454123</ixx>
					<ixy>0.0</ixy>
					<ixz>0.0</ixz>
					<iyy>0.0027019500266760588</iyy>
					<iyz>0.0</iyz>
					<izz>0.0005245470092631876</izz>
				</inertia>
			</inertial>
			<collision name="COL_link_RH7_collision">
				<pose>3.460800333748924e-16 0.00800613506243053 0.003828349872080139 1.187270164489746 -1.4989972772503691e-15 -1.109040672509908e-15</pose>
				<geometry>
					<mesh>
						<uri>model://nrp_mouse_v4_gz/meshes/collisions/COL_link_RH7_collision.dae</uri>
						<scale>0.001731784305011086 0.001731784305011086 0.001731784305011086</scale>
					</mesh>
				</geometry>
			</collision>
			<visual name="VIS_link_RH7_visual">
				<pose>3.460800333748924e-16 0.00800613506243053 0.003828349872080139 1.187270164489746 -1.4989972772503691e-15 -1.109040672509908e-15</pose>
				<geometry>
					<mesh>
						<uri>model://nrp_mouse_v4_gz/meshes/visual/VIS_link_RH7_visual.dae</uri>
						<scale>0.001731784305011086 0.001731784305011086 0.001731784305011086</scale>
					</mesh>
				</geometry>
			</visual>
		</link>
		<link name="link_RH6">
			<pose>-0.0717824636805 0.0475799362548 -0.0668744949999 -0.45378559827804554 -0.0 0.0</pose>
			<inertial>
				<mass>0.003684809897094965</mass>
				<pose>-6.881492708998849e-09 0.004876879475403939 -7.14625814097758e-05 0.44075196981430054 1.3574240091790245e-22 8.144544307509637e-22</pose>
				<inertia>
					<ixx>1.3643099919136148e-05</ixx>
					<ixy>0.0</ixy>
					<ixz>0.0</ixz>
					<iyy>1.4911000107531436e-05</iyy>
					<iyz>0.0</iyz>
					<izz>2.208459954999853e-05</izz>
				</inertia>
			</inertial>
			<visual name="VIS_link_RH6_visual">
				<pose>-1.3762985417997697e-08 0.005120680439844705 -0.0006672054478400469 0.4407519996166229 -1.8530404261810768e-15 2.0752877631480775e-16</pose>
				<geometry>
					<mesh>
						<uri>model://nrp_mouse_v4_gz/meshes/visual/VIS_link_RH6_visual.dae</uri>
						<scale>0.001731784305011086 0.001731784305011086 0.001731784305011086</scale>
					</mesh>
				</geometry>
			</visual>
		</link>
		<link name="link_RH5">
			<pose>-0.0717651458362 0.0575665344501 -0.0713344729185 0.4363323450088501 -0.0 0.0</pose>
			<inertial>
				<mass>0.004299319814890623</mass>
				<pose>0.0011101292853084033 0.005166173988143896 5.695811515238347e-05 -0.45545199513435364 -6.791130109866287e-22 -2.263710204912422e-22</pose>
				<inertia>
					<ixx>1.4719100363436155e-05</ixx>
					<ixy>0.0</ixy>
					<ixz>0.0</ixz>
					<iyy>2.3670900191063993e-05</iyy>
					<iyz>0.0</iyz>
					<izz>3.0237499231589027e-05</izz>
				</inertia>
			</inertial>
			<visual name="VIS_link_RH5_visual">
				<pose>6.881492708998849e-09 0.004913413320196014 -0.00040104135246821215 -0.45545193552970886 -1.0001140354380178e-15 1.5737717576472026e-15</pose>
				<geometry>
					<mesh>
						<uri>model://nrp_mouse_v4_gz/meshes/visual/VIS_link_RH5_visual.dae</uri>
						<scale>0.001731784305011086 0.001731784305011086 0.001731784305011086</scale>
					</mesh>
				</geometry>
			</visual>
		</link>
		<link name="link_RH4">
			<pose>-0.0711243856423 0.0671883166978 -0.0663220891302 -0.1745328903198242 -0.0 0.0</pose>
			<inertial>
				<mass>0.01053799968212843</mass>
				<pose>0.001517161192226446 0.004091583741837823 0.003480543747208742 0.1470789909362793 -6.560419068994816e-17 2.1587642629983077e-15</pose>
				<inertia>
					<ixx>6.891380326123908e-05</ixx>
					<ixy>0.0</ixy>
					<ixz>0.0</ixz>
					<iyy>9.493480320088565e-05</iyy>
					<iyz>0.0</iyz>
					<izz>0.00010201599798165262</izz>
				</inertia>
			</inertial>
			<visual name="VIS_link_RH4_visual">
				<pose>-1.5383052399049745e-09 0.004431016810455546 0.002231979473073409 0.1470789909362793 -1.156109848696532e-13 4.097820038850841e-08</pose>
				<geometry>
					<mesh>
						<uri>model://nrp_mouse_v4_gz/meshes/visual/VIS_link_RH4_visual.dae</uri>
						<scale>0.001731784305011086 0.001731784305011086 0.001731784305011086</scale>
					</mesh>
				</geometry>
			</visual>
		</link>
		<link name="link_RH3">
			<pose>-0.071782463704 0.0775051251727 -0.0692038081551 -1.239183783531189 -0.0 0.0</pose>
			<inertial>
				<mass>0.0017467200523242354</mass>
				<pose>-6.9144284536150704e-09 0.002660207882861698 -3.0815324350896844e-05 1.212030053138733 -1.5915509196530663e-17 6.672003748394749e-17</pose>
				<inertia>
					<ixx>3.0667399641970405e-06</ixx>
					<ixy>0.0</ixy>
					<ixz>0.0</ixz>
					<iyy>7.87526005296968e-06</iyy>
					<iyz>0.0</iyz>
					<izz>6.261349881242495e-06</izz>
				</inertia>
			</inertial>
			<visual name="VIS_link_RH3_visual">
				<pose>-6.9143324740858145e-09 0.0028719582950103018 0.00030988393892528165 1.212030053138733 -5.2403635208975174e-08 1.5352959792380716e-07</pose>
				<geometry>
					<mesh>
						<uri>model://nrp_mouse_v4_gz/meshes/visual/VIS_link_RH3_visual.dae</uri>
						<scale>0.001731784305011086 0.001731784305011086 0.001731784305011086</scale>
					</mesh>
				</geometry>
			</visual>
		</link>
		<link name="link_RH2">
			<pose>-0.071782463704 0.0794031356564 -0.0758394355593 -2.042035162448883 -0.0 0.0</pose>
			<inertial>
				<mass>0.0018450700445100665</mass>
				<pose>-1.0508587011069095e-08 0.0032834197327664683 -2.3204393414744118e-05 2.0214600563049316 -6.82208210478045e-17 -2.277377886492353e-15</pose>
				<inertia>
					<ixx>3.1458700959774433e-06</ixx>
					<ixy>0.0</ixy>
					<ixz>0.0</ixz>
					<iyy>8.017519576242194e-06</iyy>
					<iyz>0.0</iyz>
					<izz>6.821509941801196e-06</izz>
				</inertia>
			</inertial>
			<visual name="VIS_link_RH2_visual">
				<pose>-3.621586553699096e-09 0.003077473859717905 0.00020000370409434254 2.0214600563049316 -5.960468030252741e-08 -1.3315677449554641e-08</pose>
				<geometry>
					<mesh>
						<uri>model://nrp_mouse_v4_gz/meshes/visual/VIS_link_RH2_visual.dae</uri>
						<scale>0.001731784305011086 0.001731784305011086 0.001731784305011086</scale>
					</mesh>
				</geometry>
			</visual>
		</link>
		<link name="link_RH1">
			<pose>-0.071782463704 0.0758154249195 -0.0818279271975 -2.583087205886841 -0.0 0.0</pose>
			<inertial>
				<mass>0.05634620040655136</mass>
				<pose>-2.638467415192337e-09 0.018482583216417936 -0.0008585591155991779 2.5660500526428223 -9.53956880801526e-16 -1.6447811765934908e-15</pose>
				<inertia>
					<ixx>0.002188999904319644</ixx>
					<ixy>0.0</ixy>
					<ixz>0.0</ixz>
					<iyy>0.0009492409881204367</iyy>
					<iyz>0.0</iyz>
					<izz>0.0019243600545451045</izz>
				</inertia>
			</inertial>
			<collision name="COL_link_RH1_collision">
				<pose>-2.6185610967570773e-09 0.01920324754036784 -0.0002796673044400677 2.5660502910614014 1.4618026841078935e-15 -1.1413792577741333e-08</pose>
				<geometry>
					<mesh>
						<uri>model://nrp_mouse_v4_gz/meshes/collisions/COL_link_RH1_collision.dae</uri>
						<scale>0.001731784305011086 0.001731784305011086 0.001731784305011086</scale>
					</mesh>
				</geometry>
			</collision>
			<visual name="VIS_link_RH1_visual">
				<pose>-2.6185610967570773e-09 0.01920324754036784 -0.0002796673044400677 2.5660502910614014 1.4618026841078935e-15 -1.1413792577741333e-08</pose>
				<geometry>
					<mesh>
						<uri>model://nrp_mouse_v4_gz/meshes/visual/VIS_link_RH1_visual.dae</uri>
						<scale>0.001731784305011086 0.001731784305011086 0.001731784305011086</scale>
					</mesh>
				</geometry>
			</visual>
		</link>
		<link name="link_Tail22">
			<pose>-7.85030135515e-18 0.123417019245 0.00148078695562 -0.5235988050699234 -0.0 0.0</pose>
			<inertial>
				<mass>0.6743839979171753</mass>
				<pose>0.009519215314433893 0.029894332892695274 0.008787604255957149 0.5037789344787598 -0.0 0.0</pose>
				<inertia>
					<ixx>0.10814200341701508</ixx>
					<ixy>0.0</ixy>
					<ixz>0.0</ixz>
					<iyy>0.06384269893169403</iyy>
					<iyz>0.0</iyz>
					<izz>0.11804399639368057</izz>
				</inertia>
			</inertial>
			<collision name="collision_2_1">
				<pose>0.0 0.08658922406746683 0.011545231710726966 1.7999998331069946 -0.0 0.0</pose>
				<geometry>
					<cylinder>
						<radius>0.057726144790649414</radius>
						<length>0.057726144790649414</length>
					</cylinder>
				</geometry>
			</collision>
			<collision name="collision_1.004">
				<pose>0.0 0.03463570201367361 0.005772615855363483 1.7999998331069946 -0.0 0.0</pose>
				<geometry>
					<cylinder>
						<radius>0.057726144790649414</radius>
						<length>0.057726144790649414</length>
					</cylinder>
				</geometry>
			</collision>
			<visual name="VIS_link_Tail22_visual">
				<pose>0.005299259906669462 0.027133973485319984 0.009320968111353523 0.5037789344787598 -0.0 0.0</pose>
				<geometry>
					<mesh>
						<uri>model://nrp_mouse_v4_gz/meshes/visual/VIS_link_Tail22_visual.dae</uri>
						<scale>0.001731784305011086 0.001731784305011086 0.001731784305011086</scale>
					</mesh>
				</geometry>
			</visual>
		</link>
		<link name="link_Tail21">
			<pose>-7.85030135515e-18 0.158505092659 -0.0197229123667 -0.3141592890024186 -0.0 0.0</pose>
			<inertial>
				<mass>0.0461094006896019</mass>
				<pose>-5.772614464490491e-08 0.004455105905776691 0.0030611528944319844 0.29832297563552856 -0.0 0.0</pose>
				<inertia>
					<ixx>0.0009586440282873809</ixx>
					<ixy>0.0</ixy>
					<ixz>0.0</ixz>
					<iyy>0.001416670042090118</iyy>
					<iyz>0.0</iyz>
					<izz>0.0009389130282215774</izz>
				</inertia>
			</inertial>
			<visual name="VIS_link_Tail21_visual">
				<pose>0.0 0.0049821869583297484 0.0015319303809064877 0.2983229458332062 -0.0 0.0</pose>
				<geometry>
					<mesh>
						<uri>model://nrp_mouse_v4_gz/meshes/visual/VIS_link_Tail21_visual.dae</uri>
						<scale>0.001731784305011086 0.001731784305011086 0.001731784305011086</scale>
					</mesh>
				</geometry>
			</visual>
		</link>
		<link name="link_Tail20">
			<pose>-7.85030135515e-18 0.172283701057 -0.024617640286 -0.34906587004661566 -0.0 0.0</pose>
			<inertial>
				<mass>0.0443463996052742</mass>
				<pose>-5.772614464490491e-08 0.004534377261038003 0.0032068994692622255 0.33221402764320374 -0.0 0.0</pose>
				<inertia>
					<ixx>0.000889372022356838</ixx>
					<ixy>0.0</ixy>
					<ixz>0.0</ixz>
					<iyy>0.0013026499655097723</iyy>
					<iyz>0.0</iyz>
					<izz>0.000881228013895452</izz>
				</inertia>
			</inertial>
			<visual name="VIS_link_Tail20_visual">
				<pose>0.0 0.005058213689778768 0.001745091499060436 0.33221396803855896 -0.0 0.0</pose>
				<geometry>
					<mesh>
						<uri>model://nrp_mouse_v4_gz/meshes/visual/VIS_link_Tail20_visual.dae</uri>
						<scale>0.001731784305011086 0.001731784305011086 0.001731784305011086</scale>
					</mesh>
				</geometry>
			</visual>
		</link>
		<link name="link_Tail19">
			<pose>-7.85030135515e-18 0.186062326872 -0.0292317717058 -0.29670599102973944 -0.0 0.0</pose>
			<inertial>
				<mass>0.04178829863667488</mass>
				<pose>-5.772614464490491e-08 0.004866068650358102 0.0029101454184257136 0.27185001969337463 -0.0 0.0</pose>
				<inertia>
					<ixx>0.0007978409994393587</ixx>
					<ixy>0.0</ixy>
					<ixz>0.0</ixz>
					<iyy>0.0011695900466293097</iyy>
					<iyz>0.0</iyz>
					<izz>0.0008030299795791507</izz>
				</inertia>
			</inertial>
			<visual name="VIS_link_Tail19_visual">
				<pose>0.0 0.005271006648072785 0.0014692984750155347 0.27184996008872986 -0.0 0.0</pose>
				<geometry>
					<mesh>
						<uri>model://nrp_mouse_v4_gz/meshes/visual/VIS_link_Tail19_visual.dae</uri>
						<scale>0.001731784305011086 0.001731784305011086 0.001731784305011086</scale>
					</mesh>
				</geometry>
			</visual>
		</link>
		<link name="link_Tail18">
			<pose>-7.85030135515e-18 0.199809781852 -0.0336969714704 -0.2443461120128632 -0.0 0.0</pose>
			<inertial>
				<mass>0.03963709995150566</mass>
				<pose>-5.772614464490491e-08 0.005132282636552077 0.0026661483314427414 0.22725500166416168 -0.0 0.0</pose>
				<inertia>
					<ixx>0.0007241040002554655</ixx>
					<ixy>0.0</ixy>
					<ixz>0.0</ixz>
					<iyy>0.0010580900125205517</iyy>
					<iyz>0.0</iyz>
					<izz>0.0007386479992419481</izz>
				</inertia>
			</inertial>
			<visual name="VIS_link_Tail18_visual">
				<pose>0.0 0.005432456789264961 0.0012563025126866023 0.22725500166416168 -0.0 0.0</pose>
				<geometry>
					<mesh>
						<uri>model://nrp_mouse_v4_gz/meshes/visual/VIS_link_Tail18_visual.dae</uri>
						<scale>0.001731784305011086 0.001731784305011086 0.001731784305011086</scale>
					</mesh>
				</geometry>
			</visual>
		</link>
		<link name="link_Tail17">
			<pose>-7.85030135515e-18 0.213595914597 -0.0377956119701 -0.20943953096866608 -0.0 0.0</pose>
			<inertial>
				<mass>0.03758399933576584</mass>
				<pose>-5.772614464490491e-08 0.005347814428944275 0.0025020832230211454 0.19979903101921082 -0.0 0.0</pose>
				<inertia>
					<ixx>0.0006572079728357494</ixx>
					<ixy>0.0</ixy>
					<ixz>0.0</ixz>
					<iyy>0.0009567230008542538</iyy>
					<iyz>0.0</iyz>
					<izz>0.0006790150073356926</izz>
				</inertia>
			</inertial>
			<visual name="VIS_link_Tail17_visual">
				<pose>0.0 0.005566778365825087 0.0011273330170809004 0.19979897141456604 -0.0 0.0</pose>
				<geometry>
					<mesh>
						<uri>model://nrp_mouse_v4_gz/meshes/visual/VIS_link_Tail17_visual.dae</uri>
						<scale>0.001731784305011086 0.001731784305011086 0.001731784305011086</scale>
					</mesh>
				</geometry>
			</visual>
		</link>
		<link name="link_Tail16">
			<pose>-7.85030135515e-18 0.227414978185 -0.0415137464913 -0.20943953096866608 -0.0 0.0</pose>
			<inertial>
				<mass>0.036050599068403244</mass>
				<pose>-5.772614464490491e-08 0.005426426881278701 0.002431719960071632 0.19137896597385406 -0.0 0.0</pose>
				<inertia>
					<ixx>0.0006088269874453545</ixx>
					<ixy>0.0</ixy>
					<ixz>0.0</ixz>
					<iyy>0.0008764350204728544</iyy>
					<iyz>0.0</iyz>
					<izz>0.0006349359755404294</izz>
				</inertia>
			</inertial>
			<visual name="VIS_link_Tail16_visual">
				<pose>0.0 0.00566090514347195 0.0010967929524383635 0.19137892127037048 -0.0 0.0</pose>
				<geometry>
					<mesh>
						<uri>model://nrp_mouse_v4_gz/meshes/visual/VIS_link_Tail16_visual.dae</uri>
						<scale>0.001731784305011086 0.001731784305011086 0.001731784305011086</scale>
					</mesh>
				</geometry>
			</visual>
		</link>
		<link name="link_Tail15">
			<pose>-7.85030135515e-18 0.241206910633 -0.0450881429839 -0.2268928214907646 -0.0 0.0</pose>
			<inertial>
				<mass>0.034478798508644104</mass>
				<pose>-5.772614464490491e-08 0.0054958903890565125 0.0024614376863354437 0.20099903643131256 -0.0 0.0</pose>
				<inertia>
					<ixx>0.000561453984118998</ixx>
					<ixy>0.0</ixy>
					<ixz>0.0</ixz>
					<iyy>0.0007995360065251589</iyy>
					<iyz>0.0</iyz>
					<izz>0.0005914639914408326</izz>
				</inertia>
			</inertial>
			<visual name="VIS_link_Tail15_visual">
				<pose>0.0 0.005734929360542651 0.00116847402124165 0.2009989619255066 -0.0 0.0</pose>
				<geometry>
					<mesh>
						<uri>model://nrp_mouse_v4_gz/meshes/visual/VIS_link_Tail15_visual.dae</uri>
						<scale>0.001731784305011086 0.0017375569096840238 0.001731784305011086</scale>
					</mesh>
				</geometry>
			</visual>
		</link>
		<link name="link_Tail14">
			<pose>-7.85030135515e-18 0.254976895606 -0.0485286600799 -0.26179940253496164 -0.0 0.0</pose>
			<inertial>
				<mass>0.03289559856057167</mass>
				<pose>-5.772614464490491e-08 0.005496984546397243 0.0025849157507593645 0.22725602984428406 -0.0 0.0</pose>
				<inertia>
					<ixx>0.000516387983225286</ixx>
					<ixy>0.0</ixy>
					<ixz>0.0</ixz>
					<iyy>0.000727771024685353</iyy>
					<iyz>0.0</iyz>
					<izz>0.0005487509770318866</izz>
				</inertia>
			</inertial>
			<visual name="VIS_link_Tail14_visual">
				<pose>0.0 0.005786585285562751 0.0013381750721919161 0.22725604474544525 -0.0 0.0</pose>
				<geometry>
					<mesh>
						<uri>model://nrp_mouse_v4_gz/meshes/visual/VIS_link_Tail14_visual.dae</uri>
						<scale>0.001731784305011086 0.001731784305011086 0.001731784305011086</scale>
					</mesh>
				</geometry>
			</visual>
		</link>
		<link name="link_Tail13">
			<pose>-7.85030135515e-18 0.268725500387 -0.0518110978722 -0.19198624044656745 -0.0 0.0</pose>
			<inertial>
				<mass>0.0315014012157917</mass>
				<pose>-5.772614464490491e-08 0.005711785180189111 0.002136452311660264 0.15255603194236755 -0.0 0.0</pose>
				<inertia>
					<ixx>0.0004782830073963851</ixx>
					<ixy>0.0</ixy>
					<ixz>0.0</ixz>
					<iyy>0.0006646239780820906</iyy>
					<iyz>0.0</iyz>
					<izz>0.0005123160080984235</izz>
				</inertia>
			</inertial>
			<visual name="VIS_link_Tail13_visual">
				<pose>0.0 0.005938891643317845 0.0009131224712888297 0.15255597233772278 -0.0 0.0</pose>
				<geometry>
					<mesh>
						<uri>model://nrp_mouse_v4_gz/meshes/visual/VIS_link_Tail13_visual.dae</uri>
						<scale>0.001731784305011086 0.001731784305011086 0.001731784305011086</scale>
					</mesh>
				</geometry>
			</visual>
		</link>
		<link name="link_Tail12">
			<pose>-7.85030135515e-18 0.282467766667 -0.0549358998028 -0.2617994025349616 -0.0 0.0</pose>
			<inertial>
				<mass>0.029806099832057953</mass>
				<pose>-5.772614464490491e-08 0.005676570861623986 0.002463058277868413 0.21416500210762024 -0.0 0.0</pose>
				<inertia>
					<ixx>0.00043404600000940263</ixx>
					<ixy>0.0</ixy>
					<ixz>0.0</ixz>
					<iyy>0.0005985170137137175</iyy>
					<iyz>0.0</iyz>
					<izz>0.00046957499580457807</izz>
				</inertia>
			</inertial>
			<visual name="VIS_link_Tail12_visual">
				<pose>0.0 0.005939034434291557 0.0012917318778988829 0.21416494250297546 -0.0 0.0</pose>
				<geometry>
					<mesh>
						<uri>model://nrp_mouse_v4_gz/meshes/visual/VIS_link_Tail12_visual.dae</uri>
						<scale>0.001731784305011086 0.001731784305011086 0.001731784305011086</scale>
					</mesh>
				</geometry>
			</visual>
		</link>
		<link name="link_Tail11">
			<pose>-7.85030135515e-18 0.296195015833 -0.0579314385472 -0.22689282149076456 -0.0 0.0</pose>
			<inertial>
				<mass>0.02839050069451332</mass>
				<pose>1.2122490309803002e-06 0.005837719937510144 0.002194645654753913 0.17203298211097717 -0.0 0.0</pose>
				<inertia>
					<ixx>0.0003989200049545616</ixx>
					<ixy>0.0</ixy>
					<ixz>0.0</ixz>
					<iyy>0.0005427619908004999</iyy>
					<iyz>0.0</iyz>
					<izz>0.0004349910013843328</izz>
				</inertia>
			</inertial>
			<visual name="VIS_link_Tail11_visual">
				<pose>0.0 0.006056353562740924 0.001052352272523649 0.17203298211097717 -0.0 0.0</pose>
				<geometry>
					<mesh>
						<uri>model://nrp_mouse_v4_gz/meshes/visual/VIS_link_Tail11_visual.dae</uri>
						<scale>0.001731784305011086 0.001731784305011086 0.001731784305011086</scale>
					</mesh>
				</geometry>
			</visual>
		</link>
		<link name="link_Tail10">
			<pose>-7.85030135515e-18 0.309914203101 -0.0607658309078 -0.20943953096866602 -0.0 0.0</pose>
			<inertial>
				<mass>0.026971500366926193</mass>
				<pose>-5.772614464490491e-08 0.005960831562447311 0.002020874200866274 0.1476670354604721 -0.0 0.0</pose>
				<inertia>
					<ixx>0.00036519000423140824</ixx>
					<ixy>0.0</ixy>
					<ixz>0.0</ixz>
					<iyy>0.0004903199733234942</iyy>
					<iyz>0.0</iyz>
					<izz>0.00040151001303456724</izz>
				</inertia>
			</inertial>
			<collision name="collision_1.005">
				<pose>0.0 -3.268709036774453e-08 0.0011545217947741548 1.600000023841858 -0.0 0.0</pose>
				<geometry>
					<cylinder>
						<radius>0.057726144790649414</radius>
						<length>0.057726144790649414</length>
					</cylinder>
				</geometry>
			</collision>
			<visual name="VIS_link_Tail10_visual">
				<pose>0.0 0.006131526989094027 0.0009120730436507074 0.1476680189371109 -0.0 0.0</pose>
				<geometry>
					<mesh>
						<uri>model://nrp_mouse_v4_gz/meshes/visual/VIS_link_Tail10_visual.dae</uri>
						<scale>0.001731784305011086 0.0017375569096840238 0.001731784305011086</scale>
					</mesh>
				</geometry>
			</visual>
		</link>
		<link name="link_Tail9">
			<pose>-7.85030135515e-18 0.323627627214 -0.0634702943329 -0.20943953096866602 -0.0 0.0</pose>
			<inertial>
				<mass>0.025369400158524513</mass>
				<pose>-5.772614464490491e-08 0.006068251663634783 0.001943182148181677 0.13909600675106049 -0.0 0.0</pose>
				<inertia>
					<ixx>0.0003287130093667656</ixx>
					<ixy>0.0</ixy>
					<ixz>0.0</ixz>
					<iyy>0.0004381549952086061</iyy>
					<iyz>0.0</iyz>
					<izz>0.00036457201349548995</izz>
				</inertia>
			</inertial>
			<visual name="VIS_link_Tail9_visual">
				<pose>0.0 0.006190609765120314 0.000866730888191114 0.13909603655338287 -0.0 0.0</pose>
				<geometry>
					<mesh>
						<uri>model://nrp_mouse_v4_gz/meshes/visual/VIS_link_Tail9_visual.dae</uri>
						<scale>0.001731784305011086 0.001731784305011086 0.001731784305011086</scale>
					</mesh>
				</geometry>
			</visual>
		</link>
		<link name="link_Tail8">
			<pose>-7.85030135515e-18 0.337335278998 -0.0660344833088 -0.22689282149076453 -0.0 0.0</pose>
			<inertial>
				<mass>0.0240665003657341</mass>
				<pose>-5.772614464490491e-08 0.0061099449075854295 0.001978848924892418 0.14889000356197357 -0.0 0.0</pose>
				<inertia>
					<ixx>0.00030070700449869037</ixx>
					<ixy>0.0</ixy>
					<ixz>0.0</ixz>
					<iyy>0.0003948319936171174</iyy>
					<iyz>0.0</iyz>
					<izz>0.00033579798764549196</izz>
				</inertia>
			</inertial>
			<visual name="VIS_link_Tail8_visual">
				<pose>0.0 0.006233183840137713 0.0009349264809372926 0.14888998866081238 -0.0 0.0</pose>
				<geometry>
					<mesh>
						<uri>model://nrp_mouse_v4_gz/meshes/visual/VIS_link_Tail8_visual.dae</uri>
						<scale>0.001731784305011086 0.001731784305011086 0.001731784305011086</scale>
					</mesh>
				</geometry>
			</visual>
		</link>
		<link name="link_Tail7">
			<pose>-7.85030135515e-18 0.35104061346 -0.0684780697169 -0.12217306345701207 -0.0 0.0</pose>
			<inertial>
				<mass>0.022985100746154785</mass>
				<pose>-5.772614464490491e-08 0.006252214608224449 0.0013425792275256754 0.051204994320869446 -0.0 0.0</pose>
				<inertia>
					<ixx>0.0002788660058286041</ixx>
					<ixy>0.0</ixy>
					<ixz>0.0</ixz>
					<iyy>0.00035811300040222704</iyy>
					<iyz>0.0</iyz>
					<izz>0.0003129660035483539</izz>
				</inertia>
			</inertial>
			<visual name="VIS_link_Tail7_visual">
				<pose>0.0 0.0063120182206120035 0.0003234817685182634 0.05120498314499855 -0.0 0.0</pose>
				<geometry>
					<mesh>
						<uri>model://nrp_mouse_v4_gz/meshes/visual/VIS_link_Tail7_visual.dae</uri>
						<scale>0.001731784305011086 0.001731784305011086 0.001731784305011086</scale>
					</mesh>
				</geometry>
			</visual>
		</link>
		<link name="link_Tail6">
			<pose>-7.85030135515e-18 0.364780006365 -0.0705833842539 -0.15707964450120915 -0.0 0.0</pose>
			<inertial>
				<mass>0.02187589928507805</mass>
				<pose>-5.772614464490491e-08 0.006198217255310112 0.0015830254642708042 0.09471496194601059 -0.0 0.0</pose>
				<inertia>
					<ixx>0.00025729899061843753</ixx>
					<ixy>0.0</ixy>
					<ixz>0.0</ixz>
					<iyy>0.00032327999360859394</iyy>
					<iyz>0.0</iyz>
					<izz>0.00029023998649790883</izz>
				</inertia>
			</inertial>
			<visual name="VIS_link_Tail6_visual">
				<pose>0.0 0.006326379895895684 0.0006010295732039594 0.09471495449542999 -0.0 0.0</pose>
				<geometry>
					<mesh>
						<uri>model://nrp_mouse_v4_gz/meshes/visual/VIS_link_Tail6_visual.dae</uri>
						<scale>0.001731784305011086 0.001731784305011086 0.001731784305011086</scale>
					</mesh>
				</geometry>
			</visual>
		</link>
		<link name="link_Tail5">
			<pose>-7.85030135515e-18 0.378551155896 -0.0723451812589 -0.06981318444013584 -0.0 0.0</pose>
			<inertial>
				<mass>0.020089000463485718</mass>
				<pose>1.4431535833091085e-06 0.006058822298250277 0.0009586607492906296 0.0 -0.0 0.0</pose>
				<inertia>
					<ixx>0.0002221629983978346</ixx>
					<ixy>0.0</ixy>
					<ixz>0.0</ixz>
					<iyy>0.00028099800692871213</iyy>
					<iyz>0.0</iyz>
					<izz>0.0002530110068619251</izz>
				</inertia>
			</inertial>
			<visual name="VIS_link_Tail5_visual">
				<pose>0.0 0.006337682747670215 5.1611195317491365e-09 -1.5470485337232276e-08 -0.0 0.0</pose>
				<geometry>
					<mesh>
						<uri>model://nrp_mouse_v4_gz/meshes/visual/VIS_link_Tail5_visual.dae</uri>
						<scale>0.001731784305011086 0.0017375569096840238 0.001731784305011086</scale>
					</mesh>
				</geometry>
			</visual>
		</link>
		<link name="link_Tail4">
			<pose>-7.85030135515e-18 0.392325763305 -0.073968484304 -0.06981318444013584 -0.0 0.0</pose>
			<inertial>
				<mass>0.019669299945235252</mass>
				<pose>-2.886307429126331e-07 0.0063300064425533265 0.0009269766364852217 -7.478988983677937e-09 -0.0 0.0</pose>
				<inertia>
					<ixx>0.00021684900275431573</ixx>
					<ixy>0.0</ixy>
					<ixz>0.0</ixz>
					<iyy>0.00026067200815305114</iyy>
					<iyz>0.0</iyz>
					<izz>0.0002471579937264323</izz>
				</inertia>
			</inertial>
			<visual name="VIS_link_Tail4_visual">
				<pose>0.0 0.006372232142002332 -5.505194167199079e-08 -2.328307679988484e-08 -0.0 0.0</pose>
				<geometry>
					<mesh>
						<uri>model://nrp_mouse_v4_gz/meshes/visual/VIS_link_Tail4_visual.dae</uri>
						<scale>0.001731784305011086 0.001731784305011086 0.001731784305011086</scale>
					</mesh>
				</geometry>
			</visual>
		</link>
		<link name="link_Tail3">
			<pose>-7.85030135515e-18 0.406116534969 -0.075366078201 -0.06981318444013584 -0.0 0.0</pose>
			<inertial>
				<mass>0.018385199829936028</mass>
				<pose>-5.772614464490491e-08 0.006401582138499506 0.0008878863171517537 0.0 -0.0 0.0</pose>
				<inertia>
					<ixx>0.0001941090013133362</ixx>
					<ixy>0.0</ixy>
					<ixz>0.0</ixz>
					<iyy>0.0002300729975104332</iyy>
					<iyz>0.0</iyz>
					<izz>0.00022253200586419553</izz>
				</inertia>
			</inertial>
			<visual name="VIS_link_Tail3_visual">
				<pose>0.0 0.006429509386379095 -6.881492708998849e-09 -7.761027376318452e-09 -0.0 0.0</pose>
				<geometry>
					<mesh>
						<uri>model://nrp_mouse_v4_gz/meshes/visual/VIS_link_Tail3_visual.dae</uri>
						<scale>0.001731784305011086 0.001731784305011086 0.001731784305011086</scale>
					</mesh>
				</geometry>
			</visual>
		</link>
		<link name="link_Tail2">
			<pose>-7.85030135515e-18 0.419922316072 -0.0765402719585 -0.06981318444013584 -0.0 0.0</pose>
			<inertial>
				<mass>0.017216000705957413</mass>
				<pose>-5.772614464490491e-08 0.006483969089584818 0.0008440185215050633 0.0 -0.0 0.0</pose>
				<inertia>
					<ixx>0.00017452500469516963</ixx>
					<ixy>0.0</ixy>
					<ixz>0.0</ixz>
					<iyy>0.00020378899353090674</iyy>
					<iyz>0.0</iyz>
					<izz>0.00020068499725311995</izz>
				</inertia>
			</inertial>
			<visual name="VIS_link_Tail2_visual">
				<pose>0.0 0.0064478352315564536 1.3762985417997697e-08 -1.5522056528993744e-08 -0.0 0.0</pose>
				<geometry>
					<mesh>
						<uri>model://nrp_mouse_v4_gz/meshes/visual/VIS_link_Tail2_visual.dae</uri>
						<scale>0.001731784305011086 0.001731784305011086 0.001731784305011086</scale>
					</mesh>
				</geometry>
			</visual>
		</link>
		<link name="link_Tail1">
			<pose>-7.85030135515e-18 0.433744260895 -0.0774899110367 -0.06981318444013584 -0.0 0.0</pose>
			<inertial>
				<mass>0.01709889993071556</mass>
				<pose>0.0 0.006592482057833138 0.0007381846043870155 0.0 -0.0 0.0</pose>
				<inertia>
					<ixx>0.00017686000501271337</ixx>
					<ixy>0.0</ixy>
					<ixz>0.0</ixz>
					<iyy>0.00019329000497236848</iyy>
					<iyz>0.0</iyz>
					<izz>0.00020024999685119838</izz>
				</inertia>
			</inertial>
			<collision name="collision_1">
				<pose>0.0 -0.02020415721414537 -1.7203731772497122e-09 1.5000003576278687 -0.0 0.0</pose>
				<geometry>
					<cylinder>
						<radius>0.057726144790649414</radius>
						<length>0.057726144790649414</length>
					</cylinder>
				</geometry>
			</collision>
			<visual name="VIS_link_Tail1_visual">
				<pose>0.0 0.0077476507129219385 -6.193343438098964e-08 0.0 -0.0 0.0</pose>
				<geometry>
					<mesh>
						<uri>model://nrp_mouse_v4_gz/meshes/visual/VIS_link_Tail1_visual.dae</uri>
						<scale>0.001731784305011086 0.001731784305011086 0.001731784305011086</scale>
					</mesh>
				</geometry>
			</visual>
		</link>
		<joint name="joint_Body10" type="revolute">
			<parent>link_Body</parent>
			<child>link_Body10</child>
			<axis>
				<xyz>0.0 0.0 1.0</xyz>
				<limit>
					<lower>-0.0</lower>
					<upper>0.0</upper>
					<effort>1000.0</effort>
					<velocity>10000.0</velocity>
				</limit>
			</axis>
		</joint>
		<joint name="joint_LeftShoulder" type="revolute">
			<parent>link_Body10</parent>
			<child>link_LV</child>
			<axis>
				<xyz>1.0 0.0 0.0</xyz>
				<limit>
					<lower>-1.047200014620606</lower>
					<upper>2.094400029241212</upper>
					<effort>1000.0</effort>
					<velocity>10000.0</velocity>
				</limit>
				<dynamics>
					<spring_reference>0</spring_reference>
					<spring_stiffness>22</spring_stiffness>
					<damping>0.0</damping>
					<friction>0</friction>
				</dynamics>
			</axis>
		</joint>
		<joint name="joint_LV4" type="revolute">
			<parent>link_LV</parent>
			<child>link_LV4</child>
			<axis>
				<xyz>1.0 0.0 0.0</xyz>
				<limit>
					<lower>-0.0</lower>
					<upper>0.0</upper>
					<effort>1000.0</effort>
					<velocity>10000.0</velocity>
				</limit>
			</axis>
		</joint>
		<joint name="joint_LeftElbow" type="revolute">
			<parent>link_LV4</parent>
			<child>link_LV3</child>
			<axis>
				<xyz>1.0 0.0 0.0</xyz>
				<limit>
					<lower>-0.26179900496974273</lower>
					<upper>0.26179900496974273</upper>
					<effort>1000.0</effort>
					<velocity>10000.0</velocity>
				</limit>
				<dynamics>
					<spring_reference>0</spring_reference>
					<spring_stiffness>22</spring_stiffness>
					<damping>0.0</damping>
					<friction>0</friction>
				</dynamics>
			</axis>
		</joint>
		<joint name="joint_LV2" type="revolute">
			<parent>link_LV3</parent>
			<child>link_LV2</child>
			<axis>
				<xyz>1.0 0.0 0.0</xyz>
				<limit>
					<lower>-0.0</lower>
					<upper>0.0</upper>
					<effort>1000.0</effort>
					<velocity>10000.0</velocity>
				</limit>
			</axis>
		</joint>
		<joint name="joint_LV1" type="revolute">
			<parent>link_LV2</parent>
			<child>link_LV1</child>
			<axis>
				<xyz>1.0 0.0 0.0</xyz>
				<limit>
					<lower>-0.0</lower>
					<upper>0.0</upper>
					<effort>1000.0</effort>
					<velocity>10000.0</velocity>
				</limit>
			</axis>
		</joint>
		<joint name="joint_Neck_Horizontal" type="revolute">
			<parent>link_Body10</parent>
			<child>link_Neck</child>
			<axis>
				<xyz>0.0 0.0 1.0</xyz>
				<limit>
					<lower>-0.7853980302393938</lower>
					<upper>0.7853980302393938</upper>
					<effort>1000.0</effort>
					<velocity>10000.0</velocity>
				</limit>
				<dynamics>
					<spring_reference>0</spring_reference>
					<spring_stiffness>22</spring_stiffness>
					<damping>0.0</damping>
					<friction>0</friction>
				</dynamics>
			</axis>
		</joint>
		<joint name="joint_Neck_Vertical" type="revolute">
			<parent>link_Neck</parent>
			<child>link_Head</child>
			<axis>
				<xyz>1.0 0.0 0.0</xyz>
				<limit>
					<lower>-0.7853980302393938</lower>
					<upper>0.959931022017854</upper>
					<effort>1000.0</effort>
					<velocity>10000.0</velocity>
				</limit>
				<dynamics>
					<spring_reference>0</spring_reference>
					<spring_stiffness>22</spring_stiffness>
					<damping>0.0</damping>
					<friction>0</friction>
				</dynamics>
			</axis>
		</joint>
		<joint name="joint_RightShoulder" type="revolute">
			<parent>link_Body10</parent>
			<child>link_RV</child>
			<axis>
				<xyz>1.0 0.0 0.0</xyz>
				<limit>
					<lower>-1.047200014620606</lower>
					<upper>2.094400029241212</upper>
					<effort>1000.0</effort>
					<velocity>10000.0</velocity>
				</limit>
				<dynamics>
					<spring_reference>0</spring_reference>
					<spring_stiffness>22</spring_stiffness>
					<damping>0.0</damping>
					<friction>0</friction>
				</dynamics>
			</axis>
		</joint>
		<joint name="joint_RV4" type="revolute">
			<parent>link_RV</parent>
			<child>link_RV4</child>
			<axis>
				<xyz>1.0 0.0 0.0</xyz>
				<limit>
					<lower>-0.0</lower>
					<upper>0.0</upper>
					<effort>1000.0</effort>
					<velocity>10000.0</velocity>
				</limit>
			</axis>
		</joint>
		<joint name="joint_RightElbow" type="revolute">
			<parent>link_RV4</parent>
			<child>link_RV3</child>
			<axis>
				<xyz>1.0 0.0 0.0</xyz>
				<limit>
					<lower>-0.26179900496974273</lower>
					<upper>0.26179900496974273</upper>
					<effort>1000.0</effort>
					<velocity>10000.0</velocity>
				</limit>
				<dynamics>
					<spring_reference>0</spring_reference>
					<spring_stiffness>22</spring_stiffness>
					<damping>0.0</damping>
					<friction>0</friction>
				</dynamics>
			</axis>
		</joint>
		<joint name="joint_RV2" type="revolute">
			<parent>link_RV3</parent>
			<child>link_RV2</child>
			<axis>
				<xyz>1.0 0.0 0.0</xyz>
				<limit>
					<lower>-0.0</lower>
					<upper>0.0</upper>
					<effort>1000.0</effort>
					<velocity>10000.0</velocity>
				</limit>
			</axis>
		</joint>
		<joint name="joint_RV1" type="revolute">
			<parent>link_RV2</parent>
			<child>link_RV1</child>
			<axis>
				<xyz>1.0 0.0 0.0</xyz>
				<limit>
					<lower>-0.0</lower>
					<upper>0.0</upper>
					<effort>1000.0</effort>
					<velocity>10000.0</velocity>
				</limit>
			</axis>
		</joint>
		<joint name="joint_Body8" type="revolute">
			<parent>link_Body</parent>
			<child>link_Body8</child>
			<axis>
				<xyz>1.0 0.0 0.0</xyz>
				<limit>
					<lower>-0.0</lower>
					<upper>0.0</upper>
					<effort>1000.0</effort>
					<velocity>10000.0</velocity>
				</limit>
			</axis>
		</joint>
		<joint name="joint_Body7" type="revolute">
			<parent>link_Body8</parent>
			<child>link_Body7</child>
			<axis>
				<xyz>0.0 0.0 1.0</xyz>
				<limit>
					<lower>-0.0</lower>
					<upper>0.0</upper>
					<effort>1000.0</effort>
					<velocity>10000.0</velocity>
				</limit>
			</axis>
		</joint>
		<joint name="joint_Body6" type="revolute">
			<parent>link_Body7</parent>
			<child>link_Body6</child>
			<axis>
				<xyz>1.0 0.0 0.0</xyz>
				<limit>
					<lower>-0.0</lower>
					<upper>0.0</upper>
					<effort>1000.0</effort>
					<velocity>10000.0</velocity>
				</limit>
			</axis>
		</joint>
		<joint name="joint_Body5" type="revolute">
			<parent>link_Body6</parent>
			<child>link_Body5</child>
			<axis>
				<xyz>0.0 0.0 1.0</xyz>
				<limit>
					<lower>-0.0</lower>
					<upper>0.0</upper>
					<effort>1000.0</effort>
					<velocity>10000.0</velocity>
				</limit>
			</axis>
		</joint>
		<joint name="joint_Body4" type="revolute">
			<parent>link_Body5</parent>
			<child>link_Body4</child>
			<axis>
				<xyz>1.0 0.0 0.0</xyz>
				<limit>
					<lower>-0.0</lower>
					<upper>0.0</upper>
					<effort>1000.0</effort>
					<velocity>10000.0</velocity>
				</limit>
			</axis>
		</joint>
		<joint name="joint_Body3" type="revolute">
			<parent>link_Body4</parent>
			<child>link_Body3</child>
			<axis>
				<xyz>0.0 0.0 1.0</xyz>
				<limit>
					<lower>-0.0</lower>
					<upper>0.0</upper>
					<effort>1000.0</effort>
					<velocity>10000.0</velocity>
				</limit>
			</axis>
		</joint>
		<joint name="joint_Body2" type="revolute">
			<parent>link_Body3</parent>
			<child>link_Body2</child>
			<axis>
				<xyz>1.0 0.0 0.0</xyz>
				<limit>
					<lower>-0.0</lower>
					<upper>0.0</upper>
					<effort>1000.0</effort>
					<velocity>10000.0</velocity>
				</limit>
			</axis>
		</joint>
		<joint name="joint_Body1" type="revolute">
			<parent>link_Body2</parent>
			<child>link_Body1</child>
			<axis>
				<xyz>0.0 0.0 1.0</xyz>
				<limit>
					<lower>-0.0</lower>
					<upper>0.0</upper>
					<effort>1000.0</effort>
					<velocity>10000.0</velocity>
				</limit>
			</axis>
		</joint>
		<joint name="joint_LeftHip" type="revolute">
			<parent>link_Body1</parent>
			<child>link_LH</child>
			<axis>
				<xyz>1.0 0.0 0.0</xyz>
				<limit>
					<lower>-0.8726650254713283</lower>
					<upper>1.5708000552204227</upper>
					<effort>1000.0</effort>
					<velocity>10000.0</velocity>
				</limit>
				<dynamics>
					<spring_reference>0</spring_reference>
					<spring_stiffness>22</spring_stiffness>
					<damping>0.0</damping>
					<friction>0</friction>
				</dynamics>
			</axis>
		</joint>
		<joint name="joint_LH10" type="revolute">
			<parent>link_LH</parent>
			<child>link_LH10</child>
			<axis>
				<xyz>1.0 0.0 0.0</xyz>
				<limit>
					<lower>-0.0</lower>
					<upper>0.0</upper>
					<effort>1000.0</effort>
					<velocity>10000.0</velocity>
				</limit>
			</axis>
		</joint>
		<joint name="joint_LeftKnee" type="revolute">
			<parent>link_LH10</parent>
			<child>link_LH9</child>
			<axis>
				<xyz>1.0 0.0 0.0</xyz>
				<limit>
					<lower>-0.26179900496974273</lower>
					<upper>0.26179900496974273</upper>
					<effort>1000.0</effort>
					<velocity>10000.0</velocity>
				</limit>
				<dynamics>
					<spring_reference>0</spring_reference>
					<spring_stiffness>22</spring_stiffness>
					<damping>0.0</damping>
					<friction>0</friction>
				</dynamics>
			</axis>
		</joint>
		<joint name="joint_LH8" type="revolute">
			<parent>link_LH9</parent>
			<child>link_LH8</child>
			<axis>
				<xyz>1.0 0.0 0.0</xyz>
				<limit>
					<lower>-0.0</lower>
					<upper>0.0</upper>
					<effort>1000.0</effort>
					<velocity>10000.0</velocity>
				</limit>
			</axis>
		</joint>
		<joint name="joint_LH7" type="revolute">
			<parent>link_LH8</parent>
			<child>link_LH7</child>
			<axis>
				<xyz>1.0 0.0 0.0</xyz>
				<limit>
					<lower>-0.0</lower>
					<upper>0.0</upper>
					<effort>1000.0</effort>
					<velocity>10000.0</velocity>
				</limit>
			</axis>
		</joint>
		<joint name="joint_LH6" type="revolute">
			<parent>link_LH7</parent>
			<child>link_LH6</child>
			<axis>
				<xyz>1.0 0.0 0.0</xyz>
				<limit>
					<lower>-0.0</lower>
					<upper>0.0</upper>
					<effort>1000.0</effort>
					<velocity>10000.0</velocity>
				</limit>
			</axis>
		</joint>
		<joint name="joint_LeftAnkle" type="revolute">
			<parent>link_LH6</parent>
			<child>link_LH5</child>
			<axis>
				<xyz>1.0 0.0 0.0</xyz>
				<limit>
					<lower>-0.26179900496974273</lower>
					<upper>0.26179900496974273</upper>
					<effort>1000.0</effort>
					<velocity>10000.0</velocity>
				</limit>
				<dynamics>
					<spring_reference>0</spring_reference>
					<spring_stiffness>22</spring_stiffness>
					<damping>0.0</damping>
					<friction>0</friction>
				</dynamics>
			</axis>
		</joint>
		<joint name="joint_LH4" type="revolute">
			<parent>link_LH5</parent>
			<child>link_LH4</child>
			<axis>
				<xyz>1.0 0.0 0.0</xyz>
				<limit>
					<lower>-0.0</lower>
					<upper>0.0</upper>
					<effort>1000.0</effort>
					<velocity>10000.0</velocity>
				</limit>
			</axis>
		</joint>
		<joint name="joint_LH3" type="revolute">
			<parent>link_LH4</parent>
			<child>link_LH3</child>
			<axis>
				<xyz>1.0 0.0 0.0</xyz>
				<limit>
					<lower>-0.0</lower>
					<upper>0.0</upper>
					<effort>1000.0</effort>
					<velocity>10000.0</velocity>
				</limit>
			</axis>
		</joint>
		<joint name="joint_LeftFoot" type="revolute">
			<parent>link_LH3</parent>
			<child>link_LH2</child>
			<axis>
				<xyz>1.0 0.0 0.0</xyz>
				<limit>
					<lower>-0.26179900496974273</lower>
					<upper>0.26179900496974273</upper>
					<effort>1000.0</effort>
					<velocity>10000.0</velocity>
				</limit>
				<dynamics>
					<spring_reference>0</spring_reference>
					<spring_stiffness>22</spring_stiffness>
					<damping>0.0</damping>
					<friction>0</friction>
				</dynamics>
			</axis>
		</joint>
		<joint name="joint_LH1" type="revolute">
			<parent>link_LH2</parent>
			<child>link_LH1</child>
			<axis>
				<xyz>1.0 0.0 0.0</xyz>
				<limit>
					<lower>-0.0</lower>
					<upper>0.0</upper>
					<effort>1000.0</effort>
					<velocity>10000.0</velocity>
				</limit>
			</axis>
		</joint>
		<joint name="joint_RightHip" type="revolute">
			<parent>link_Body1</parent>
			<child>link_RH</child>
			<axis>
				<xyz>1.0 0.0 0.0</xyz>
				<limit>
					<lower>-0.8726650254713283</lower>
					<upper>1.5708000552204227</upper>
					<effort>1000.0</effort>
					<velocity>10000.0</velocity>
				</limit>
				<dynamics>
					<spring_reference>0</spring_reference>
					<spring_stiffness>22</spring_stiffness>
					<damping>1.0</damping>
					<friction>0</friction>
				</dynamics>
			</axis>
		</joint>
		<joint name="joint_RH10" type="revolute">
			<parent>link_RH</parent>
			<child>link_RH10</child>
			<axis>
				<xyz>1.0 0.0 0.0</xyz>
				<limit>
					<lower>-0.0</lower>
					<upper>0.0</upper>
					<effort>1000.0</effort>
					<velocity>10000.0</velocity>
				</limit>
			</axis>
		</joint>
		<joint name="joint_RightKnee" type="revolute">
			<parent>link_RH10</parent>
			<child>link_RH9</child>
			<axis>
				<xyz>1.0 0.0 0.0</xyz>
				<limit>
					<lower>-0.26179900496974273</lower>
					<upper>0.26179900496974273</upper>
					<effort>1000.0</effort>
					<velocity>10000.0</velocity>
				</limit>
				<dynamics>
					<spring_reference>0</spring_reference>
					<spring_stiffness>22</spring_stiffness>
					<damping>1.0</damping>
					<friction>0</friction>
				</dynamics>
			</axis>
		</joint>
		<joint name="joint_RH8" type="revolute">
			<parent>link_RH9</parent>
			<child>link_RH8</child>
			<axis>
				<xyz>1.0 0.0 0.0</xyz>
				<limit>
					<lower>-0.0</lower>
					<upper>0.0</upper>
					<effort>1000.0</effort>
					<velocity>10000.0</velocity>
				</limit>
			</axis>
		</joint>
		<joint name="joint_RH7" type="revolute">
			<parent>link_RH8</parent>
			<child>link_RH7</child>
			<axis>
				<xyz>1.0 0.0 0.0</xyz>
				<limit>
					<lower>-0.0</lower>
					<upper>0.0</upper>
					<effort>1000.0</effort>
					<velocity>10000.0</velocity>
				</limit>
			</axis>
		</joint>
		<joint name="joint_RH6" type="revolute">
			<parent>link_RH7</parent>
			<child>link_RH6</child>
			<axis>
				<xyz>1.0 0.0 0.0</xyz>
				<limit>
					<lower>-0.0</lower>
					<upper>0.0</upper>
					<effort>1000.0</effort>
					<velocity>10000.0</velocity>
				</limit>
			</axis>
		</joint>
		<joint name="joint_RightAnkle" type="revolute">
			<parent>link_RH6</parent>
			<child>link_RH5</child>
			<axis>
				<xyz>1.0 0.0 0.0</xyz>
				<limit>
					<lower>-0.26179900496974273</lower>
					<upper>0.26179900496974273</upper>
					<effort>1000.0</effort>
					<velocity>10000.0</velocity>
				</limit>
				<dynamics>
					<spring_reference>0</spring_reference>
					<spring_stiffness>22</spring_stiffness>
					<damping>1.0</damping>
					<friction>0</friction>
				</dynamics>
			</axis>
		</joint>
		<joint name="joint_RH4" type="revolute">
			<parent>link_RH5</parent>
			<child>link_RH4</child>
			<axis>
				<xyz>1.0 0.0 0.0</xyz>
				<limit>
					<lower>-0.0</lower>
					<upper>0.0</upper>
					<effort>1000.0</effort>
					<velocity>10000.0</velocity>
				</limit>
			</axis>
		</joint>
		<joint name="joint_RH3" type="revolute">
			<parent>link_RH4</parent>
			<child>link_RH3</child>
			<axis>
				<xyz>1.0 0.0 0.0</xyz>
				<limit>
					<lower>-0.0</lower>
					<upper>0.0</upper>
					<effort>1000.0</effort>
					<velocity>10000.0</velocity>
				</limit>
			</axis>
		</joint>
		<joint name="joint_RightFoot" type="revolute">
			<parent>link_RH3</parent>
			<child>link_RH2</child>
			<axis>
				<xyz>1.0 0.0 0.0</xyz>
				<limit>
					<lower>-0.26179900496974273</lower>
					<upper>0.26179900496974273</upper>
					<effort>1000.0</effort>
					<velocity>10000.0</velocity>
				</limit>
				<dynamics>
					<spring_reference>0</spring_reference>
					<spring_stiffness>22</spring_stiffness>
					<damping>1.0</damping>
					<friction>0</friction>
				</dynamics>
			</axis>
		</joint>
		<joint name="joint_RH1" type="revolute">
			<parent>link_RH2</parent>
			<child>link_RH1</child>
			<axis>
				<xyz>1.0 0.0 0.0</xyz>
				<limit>
					<lower>-0.0</lower>
					<upper>0.0</upper>
					<effort>1000.0</effort>
					<velocity>10000.0</velocity>
				</limit>
			</axis>
		</joint>
		<joint name="joint_Tail22" type="revolute">
			<parent>link_Body1</parent>
			<child>link_Tail22</child>
			<axis>
				<xyz>1.0 0.0 0.0</xyz>
				<limit>
					<lower>-0.06981320336928681</lower>
					<upper>1.4835299973532345</upper>
					<effort>1000.0</effort>
					<velocity>10000.0</velocity>
				</limit>
				<dynamics>
					<spring_reference>0</spring_reference>
					<spring_stiffness>22</spring_stiffness>
					<damping>1.0</damping>
					<friction>0</friction>
				</dynamics>
			</axis>
		</joint>
		<joint name="joint_Tail21" type="revolute">
			<parent>link_Tail22</parent>
			<child>link_Tail21</child>
			<axis>
				<xyz>0.0 0.0 1.0</xyz>
				<limit>
					<lower>-0.4886919908213305</lower>
					<upper>0.4886919908213305</upper>
					<effort>1000.0</effort>
					<velocity>10000.0</velocity>
				</limit>
				<dynamics>
					<spring_reference>0</spring_reference>
					<spring_stiffness>22</spring_stiffness>
					<damping>1.0</damping>
					<friction>0</friction>
				</dynamics>
			</axis>
		</joint>
		<joint name="joint_Tail20" type="revolute">
			<parent>link_Tail21</parent>
			<child>link_Tail20</child>
			<axis>
				<xyz>0.0 0.0 1.0</xyz>
				<limit>
					<lower>-0.4886919908213305</lower>
					<upper>0.4886919908213305</upper>
					<effort>1000.0</effort>
					<velocity>10000.0</velocity>
				</limit>
				<dynamics>
					<spring_reference>0</spring_reference>
					<spring_stiffness>22</spring_stiffness>
					<damping>1.0</damping>
					<friction>0</friction>
				</dynamics>
			</axis>
		</joint>
		<joint name="joint_Tail19" type="revolute">
			<parent>link_Tail20</parent>
			<child>link_Tail19</child>
			<axis>
				<xyz>0.0 0.0 1.0</xyz>
				<limit>
					<lower>-0.5061449837356512</lower>
					<upper>0.5061449837356512</upper>
					<effort>1000.0</effort>
					<velocity>10000.0</velocity>
				</limit>
				<dynamics>
					<spring_reference>0</spring_reference>
					<spring_stiffness>22</spring_stiffness>
					<damping>1.0</damping>
					<friction>0</friction>
				</dynamics>
			</axis>
		</joint>
		<joint name="joint_Tail18" type="revolute">
			<parent>link_Tail19</parent>
			<child>link_Tail18</child>
			<axis>
				<xyz>0.0 0.0 1.0</xyz>
				<limit>
					<lower>-0.5061449837356512</lower>
					<upper>0.5061449837356512</upper>
					<effort>1000.0</effort>
					<velocity>10000.0</velocity>
				</limit>
				<dynamics>
					<spring_reference>0</spring_reference>
					<spring_stiffness>22</spring_stiffness>
					<damping>1.0</damping>
					<friction>0</friction>
				</dynamics>
			</axis>
		</joint>
		<joint name="joint_Tail17" type="revolute">
			<parent>link_Tail18</parent>
			<child>link_Tail17</child>
			<axis>
				<xyz>0.0 0.0 1.0</xyz>
				<limit>
					<lower>-0.5235990086248943</lower>
					<upper>0.5235990086248943</upper>
					<effort>1000.0</effort>
					<velocity>10000.0</velocity>
				</limit>
				<dynamics>
					<spring_reference>0</spring_reference>
					<spring_stiffness>22</spring_stiffness>
					<damping>1.0</damping>
					<friction>0</friction>
				</dynamics>
			</axis>
		</joint>
		<joint name="joint_Tail16" type="revolute">
			<parent>link_Tail17</parent>
			<child>link_Tail16</child>
			<axis>
				<xyz>0.0 0.0 1.0</xyz>
				<limit>
					<lower>-0.5235990086248943</lower>
					<upper>0.5235990086248943</upper>
					<effort>1000.0</effort>
					<velocity>10000.0</velocity>
				</limit>
				<dynamics>
					<spring_reference>0</spring_reference>
					<spring_stiffness>22</spring_stiffness>
					<damping>1.0</damping>
					<friction>0</friction>
				</dynamics>
			</axis>
		</joint>
		<joint name="joint_Tail15" type="revolute">
			<parent>link_Tail16</parent>
			<child>link_Tail15</child>
			<axis>
				<xyz>0.0 0.0 1.0</xyz>
				<limit>
					<lower>-0.541052001539215</lower>
					<upper>0.541052001539215</upper>
					<effort>1000.0</effort>
					<velocity>10000.0</velocity>
				</limit>
				<dynamics>
					<spring_reference>0</spring_reference>
					<spring_stiffness>22</spring_stiffness>
					<damping>1.0</damping>
					<friction>0</friction>
				</dynamics>
			</axis>
		</joint>
		<joint name="joint_Tail14" type="revolute">
			<parent>link_Tail15</parent>
			<child>link_Tail14</child>
			<axis>
				<xyz>0.0 0.0 1.0</xyz>
				<limit>
					<lower>-0.5585049944535355</lower>
					<upper>0.5585049944535355</upper>
					<effort>1000.0</effort>
					<velocity>10000.0</velocity>
				</limit>
				<dynamics>
					<spring_reference>0</spring_reference>
					<spring_stiffness>22</spring_stiffness>
					<damping>1.0</damping>
					<friction>0</friction>
				</dynamics>
			</axis>
		</joint>
		<joint name="joint_Tail13" type="revolute">
			<parent>link_Tail14</parent>
			<child>link_Tail13</child>
			<axis>
				<xyz>0.0 0.0 1.0</xyz>
				<limit>
					<lower>-0.5585049944535355</lower>
					<upper>0.5585049944535355</upper>
					<effort>1000.0</effort>
					<velocity>10000.0</velocity>
				</limit>
				<dynamics>
					<spring_reference>0</spring_reference>
					<spring_stiffness>22</spring_stiffness>
					<damping>1.0</damping>
					<friction>0</friction>
				</dynamics>
			</axis>
		</joint>
		<joint name="joint_Tail12" type="revolute">
			<parent>link_Tail13</parent>
			<child>link_Tail12</child>
			<axis>
				<xyz>0.0 0.0 1.0</xyz>
				<limit>
					<lower>-0.575958986053265</lower>
					<upper>0.575958986053265</upper>
					<effort>1000.0</effort>
					<velocity>10000.0</velocity>
				</limit>
				<dynamics>
					<spring_reference>0</spring_reference>
					<spring_stiffness>22</spring_stiffness>
					<damping>1.0</damping>
					<friction>0</friction>
				</dynamics>
			</axis>
		</joint>
		<joint name="joint_Tail11" type="revolute">
			<parent>link_Tail12</parent>
			<child>link_Tail11</child>
			<axis>
				<xyz>0.0 0.0 1.0</xyz>
				<limit>
					<lower>-0.5934120122570993</lower>
					<upper>0.5934120122570993</upper>
					<effort>1000.0</effort>
					<velocity>10000.0</velocity>
				</limit>
				<dynamics>
					<spring_reference>0</spring_reference>
					<spring_stiffness>22</spring_stiffness>
					<damping>1.0</damping>
					<friction>0</friction>
				</dynamics>
			</axis>
		</joint>
		<joint name="joint_Tail10" type="revolute">
			<parent>link_Tail11</parent>
			<child>link_Tail10</child>
			<axis>
				<xyz>0.0 0.0 1.0</xyz>
				<limit>
					<lower>-0.5934120122570993</lower>
					<upper>0.5934120122570993</upper>
					<effort>1000.0</effort>
					<velocity>10000.0</velocity>
				</limit>
				<dynamics>
					<spring_reference>0</spring_reference>
					<spring_stiffness>22</spring_stiffness>
					<damping>1.0</damping>
					<friction>0</friction>
				</dynamics>
			</axis>
		</joint>
		<joint name="joint_Tail9" type="revolute">
			<parent>link_Tail10</parent>
			<child>link_Tail9</child>
			<axis>
				<xyz>0.0 0.0 1.0</xyz>
				<limit>
					<lower>-0.6108649718819064</lower>
					<upper>0.6108649718819064</upper>
					<effort>1000.0</effort>
					<velocity>10000.0</velocity>
				</limit>
				<dynamics>
					<spring_reference>0</spring_reference>
					<spring_stiffness>22</spring_stiffness>
					<damping>1.0</damping>
					<friction>0</friction>
				</dynamics>
			</axis>
		</joint>
		<joint name="joint_Tail8" type="revolute">
			<parent>link_Tail9</parent>
			<child>link_Tail8</child>
			<axis>
				<xyz>0.0 0.0 1.0</xyz>
				<limit>
					<lower>-0.6283189967711494</lower>
					<upper>0.6283189967711494</upper>
					<effort>1000.0</effort>
					<velocity>10000.0</velocity>
				</limit>
				<dynamics>
					<spring_reference>0</spring_reference>
					<spring_stiffness>22</spring_stiffness>
					<damping>1.0</damping>
					<friction>0</friction>
				</dynamics>
			</axis>
		</joint>
		<joint name="joint_Tail7" type="revolute">
			<parent>link_Tail8</parent>
			<child>link_Tail7</child>
			<axis>
				<xyz>0.0 0.0 1.0</xyz>
				<limit>
					<lower>-0.6283189967711494</lower>
					<upper>0.6283189967711494</upper>
					<effort>1000.0</effort>
					<velocity>10000.0</velocity>
				</limit>
				<dynamics>
					<spring_reference>0</spring_reference>
					<spring_stiffness>22</spring_stiffness>
					<damping>1.0</damping>
					<friction>0</friction>
				</dynamics>
			</axis>
		</joint>
		<joint name="joint_Tail6" type="revolute">
			<parent>link_Tail7</parent>
			<child>link_Tail6</child>
			<axis>
				<xyz>0.0 0.0 1.0</xyz>
				<limit>
					<lower>-0.6457720229749837</lower>
					<upper>0.6457720229749837</upper>
					<effort>1000.0</effort>
					<velocity>10000.0</velocity>
				</limit>
				<dynamics>
					<spring_reference>0</spring_reference>
					<spring_stiffness>22</spring_stiffness>
					<damping>1.0</damping>
					<friction>0</friction>
				</dynamics>
			</axis>
		</joint>
		<joint name="joint_Tail5" type="revolute">
			<parent>link_Tail6</parent>
			<child>link_Tail5</child>
			<axis>
				<xyz>0.0 0.0 1.0</xyz>
				<limit>
					<lower>-0.6632249825997907</lower>
					<upper>0.6632249825997907</upper>
					<effort>1000.0</effort>
					<velocity>10000.0</velocity>
				</limit>
				<dynamics>
					<spring_reference>0</spring_reference>
					<spring_stiffness>22</spring_stiffness>
					<damping>1.0</damping>
					<friction>0</friction>
				</dynamics>
			</axis>
		</joint>
		<joint name="joint_Tail4" type="revolute">
			<parent>link_Tail5</parent>
			<child>link_Tail4</child>
			<axis>
				<xyz>0.0 0.0 1.0</xyz>
				<limit>
					<lower>-0.6806780088036251</lower>
					<upper>0.6806780088036251</upper>
					<effort>1000.0</effort>
					<velocity>10000.0</velocity>
				</limit>
				<dynamics>
					<spring_reference>0</spring_reference>
					<spring_stiffness>22</spring_stiffness>
					<damping>1.0</damping>
					<friction>0</friction>
				</dynamics>
			</axis>
		</joint>
		<joint name="joint_Tail3" type="revolute">
			<parent>link_Tail4</parent>
			<child>link_Tail3</child>
			<axis>
				<xyz>0.0 0.0 1.0</xyz>
				<limit>
					<lower>-0.6981319671138408</lower>
					<upper>0.6981319671138408</upper>
					<effort>1000.0</effort>
					<velocity>10000.0</velocity>
				</limit>
				<dynamics>
					<spring_reference>0</spring_reference>
					<spring_stiffness>22</spring_stiffness>
					<damping>1.0</damping>
					<friction>0</friction>
				</dynamics>
			</axis>
		</joint>
		<joint name="joint_Tail2" type="revolute">
			<parent>link_Tail3</parent>
			<child>link_Tail2</child>
			<axis>
				<xyz>0.0 0.0 1.0</xyz>
				<limit>
					<lower>-0.7155849933176751</lower>
					<upper>0.7155849933176751</upper>
					<effort>1000.0</effort>
					<velocity>10000.0</velocity>
				</limit>
				<dynamics>
					<spring_reference>0</spring_reference>
					<spring_stiffness>22</spring_stiffness>
					<damping>1.0</damping>
					<friction>0</friction>
				</dynamics>
			</axis>
		</joint>
		<joint name="joint_Tail1" type="revolute">
			<parent>link_Tail2</parent>
			<child>link_Tail1</child>
			<axis>
				<xyz>0.0 0.0 1.0</xyz>
				<limit>
					<lower>-0.7330380195215094</lower>
					<upper>0.7330380195215094</upper>
					<effort>1000.0</effort>
					<velocity>10000.0</velocity>
				</limit>
				<dynamics>
					<spring_reference>0</spring_reference>
					<spring_stiffness>22</spring_stiffness>
					<damping>1.0</damping>
					<friction>0</friction>
				</dynamics>
			</axis>
		</joint>
		    <plugin name='generic_controller' filename='libgeneric_controller_plugin.so'>
      <controller joint_name='joint_RightShoulder'>
        <type>position</type>
        <pid>100.0 1.0 0.1</pid>      </controller>
      <controller joint_name='joint_LeftShoulder'>
        <type>position</type>
        <pid>100.0 1.0 0.1</pid>      </controller>
      <controller joint_name='joint_RightHip'>
        <type>position</type>
        <pid>100.0 1.0 0.1</pid>      </controller>
      <controller joint_name='joint_LeftHip'>
        <type>position</type>
        <pid>100.0 1.0 0.1</pid>
      </controller>
      <controller joint_name='joint_Neck_Vertical'>
        <type>position</type>
        <pid>100.0 1.0 0.1</pid>      </controller>
      <controller joint_name='joint_Neck_Horizontal'>
        <type>position</type>
        <pid>100.0 1.0 0.1</pid>      </controller>
      <!-- controlers for foreleg tendons -->
      <controller joint_name='joint_LeftElbow'>
        <type>position</type>
        <pid>100.0 1.0 0.1</pid>      </controller>
      <controller joint_name='joint_RightElbow'>
        <type>position</type>
        <pid>100.0 1.0 0.1</pid>      </controller>
      <!-- controlers for mimik joints -->
      <controller joint_name='joint_LeftKnee'>
        <type>position</type>
        <pid>100.0 1.0 0.1</pid>      </controller>
      <controller joint_name='joint_RightKnee'>
        <type>position</type>
        <pid>100.0 1.0 0.1</pid>      </controller>
    </plugin>
	<plugin name='left_hindleg_mimic_plugin' filename='libroboticsgroup_gazebo_mimic_joint_plugin.so'>
      <joint>joint_LeftKnee</joint>
      <mimicJoint>joint_LeftAnkle</mimicJoint>
      <multiplier>-0.5</multiplier>
      <offset>0</offset>
      <sensitiveness>0.0</sensitiveness>
      <maxEffort>1000.0</maxEffort>
    </plugin>
    <plugin name='left_hindleg_mimic_plugin' filename='libroboticsgroup_gazebo_mimic_joint_plugin.so'>
      <joint>joint_RightKnee</joint>
      <mimicJoint>joint_RightAnkle</mimicJoint>
      <multiplier>-0.5</multiplier>
      <offset>0</offset>
      <sensitiveness>0.0</sensitiveness>
      <maxEffort>1000.0</maxEffort>
    </plugin> 

	</model>
</sdf>
